Workbook

Sheet 입력
A1: 입력정수
A3: 공법명 | B3: 페 블 테 크
A4: 공사명 | B4: 전북 전주시 완산구 상림동 596 다세대주택 신축공사
A5: 검토일 | B5: =TODAY() -> 45870
A6: 기초형식 | B6: 설계하중 | C6: 지상 | D6: 150
B8: 기초형식 | C8: 매트기초 | D8: THK 500
A13: 기초하부지층 | B13: N값 | C13: 4/30 | D13: 8/30 | E13: =+E20 -> 실트질 모래
A14: 건물규모 | C14: 지상4층
A16: 페블두께 | B16: =+지상1층!T92 -> 500 | C16: =+지상1층!X92 -> 1
A17: 설계하중 | B17: =+D6 -> 150
A19: 토층 | B19: 두께 | D19: 단위중량 | E19: 비고 | F19: 분류기호 | G19: N값
A20: 매립층 | B20: 0 | C20: 3.5 | D20: 18 | E20: 실트질 모래 | F20: SM | G20: 4 | H20: 8
A21: 퇴적층 | B21: =+C20 -> 3.5 | C21: 6.7 | D21: 18 | E21: 실트질 모래 | F21: SM | G21: 4 | H21: 11
A22: 풍화암 | B22: =+C21 -> 6.7 | C22: 15 | D22: 20 | F22: WR | G22: 50/7 | H22: 50/2
A25: 지하수위 | B25: 2.72 | C25: m | D25: BH-1
A27: 1. 구조도면 또는 구조안전확인서를 보고 지내력기초 000kN/m2을 확인하여 설계하중을 기입한다.
A28: 2. 주상도를 보고 토층의 종류와 두께 분류기호 N값을 기입한다
A29: 3. 주상도의 적당한 위치와 약한 구간을 골라 주상도를 선택하고 지하수위를 기입한다

Sheet 검토서표지
B5: =입력!B3 -> 페 블 테 크
B6: 지반보강공법 검토서
B8: =입력!B4 -> 전북 전주시 완산구 상림동 596 다세대주택 신축공사
B26: =TEXT(입력!B5, "YYYY-MM") -> 2025-08

Sheet 검토서갑지
V2: =입력!B5 -> 45870
A3: ○ | B3: 공 사 명 : | F3: =입력!B4 -> 전북 전주시 완산구 상림동 596 다세대주택 신축공사
A4: ○ | B4: 검 토 내 용 : | F4: 페블테크 지반보강공법 검토
A5: ○ 검 토 자 : | B5: 검 토 자 : | F5: 토질 및 기초 기술사 김선학
B7: 지내력이 부족한 지반에 대하여 지반보강 공법으로 페블테크 공법 제안
B9: 기 초 형 식 | G9: ="- "&입력!C6&" "&입력!D6&" kN/㎡ " -> - 지상 150 kN/㎡
B10: 기 초 하 부 지 층 | G10: ="- "&입력!B13&" "&입력!C13&"~"&" "&입력!D13&"의 "&입력!E13&"" -> - N값 4/30~ 8/30의 실트질 모래
B11: 건 물 규 모 | G11: ="- "&입력!C14 -> - 지상4층
A13: 1. | B13: 검 토
B14: 시 추 위 치 도 | P14: 기초레벨 검토
A17: 2. | B17: 페블테크 공법 제안
B18: 페블테크 보강
A20: =" - 페블테크 치환 T= " & 입력!B16 & " mm + 매트"&입력!C16&"겹 " & "적용시 설계하중 " & 입력!B17 & " kN/㎡에 대하여 기초안정성 확보" -> - 페블테크 치환 T= 500 mm + 매트1겹 적용시 설계하중 150 kN/㎡에 대하여 기초안정성 확보
A21: - 페블테크 치환 상단에서 가시설 브레이싱과의 순작업공간은 3.5톤 콤비로라 H=2.3m,10톤 로라 H=3.2m이상을 확보필요
A22: - 페블테크 치환공법 적용시 버림콘크리트 하부의 잡석 불필요
A23: - 지반조건이 다를 경우, 페블테크의 물량은 변경될 수 있으며, 치환 깊이 재검토 필요
A24: - 페블테크 시공을 위한 터파기는 원도급사분
A25: =" - 페블테크 치환 T= " & 입력!#REF! & " mm + PET MAT " & 입력!B21 & "단 적용시 설계하중 " & 입력!#REF! & " kN/㎡에 대하여 기초안정성 확보" -> #REF!

Sheet 계산서표지
B5: =입력!B3 -> 페 블 테 크
B6: 지반보강공법 검토서
B8: =입력!B4 -> 전북 전주시 완산구 상림동 596 다세대주택 신축공사
B26: =TEXT(입력!B5, "YYYY-MM") -> 2025-08

Sheet 제출문
A3: 제 출 문
A7: 사 업 주 귀중
A13: =입력!B4 -> 전북 전주시 완산구 상림동 596 다세대주택 신축공사
A14: 의 페블테크 지반보강공법의 검토서를 제출합니다.
A26: =검토서표지!B26 -> 2025-08
E32: ㈜ 지반디자인앤솔루션
E33: 전남 나주시 우정로10 사동305호
E34: 대표이사 김 홍 수(인)

Sheet 계산서인장
A3: ○ | B3: 공 사 명 : | H3: =입력!B4 -> 전북 전주시 완산구 상림동 596 다세대주택 신축공사
A4: ○ | B4: 설 계 하 중 : | H4: =입력!B17&" kN/m2" -> 150 kN/m2
A5: ○ | B5: 기준침하량 : | H5: 25.4 mm
A6: ○ | B6: 치 환 두 께 : | H6: ="페블테크 "&입력!B16&"mm + PET MAT "&입력!C16&"겹" -> 페블테크 500mm + PET MAT 1겹
A8: 본 검토서는 페블테크 공법에 의한 지반보강 후의 설계하중을 검토하기 위한 목적으로 검토하였으며,
A10: =" 페블테크 지반보강공법에 의한 지반보강 후 지내력 검토결과 페블테크 "&입력!B16&"mm + PETMAT "&입력!C16&"겹 적용시" -> 페블테크 지반보강공법에 의한 지반보강 후 지내력 검토결과 페블테크 500mm + PETMAT 1겹 적용시
B12: ="설계하중 "&입력!B17&"kN/m에 대하여 안전성을 확보하고 있는 것으로 검토되었음." -> 설계하중 150kN/m에 대하여 안전성을 확보하고 있는 것으로 검토되었음.
A14: =제출문!A26 -> 2025-08
U16: 토질 및 기초기술사
U17: 김 선 학 (인)

Sheet 자격증사본

Sheet 계산서 갑지
V2: =입력!B5 -> 45870
A3: ○ | B3: 공 사 명 : | F3: =입력!B4 -> 전북 전주시 완산구 상림동 596 다세대주택 신축공사
A4: ○ | B4: 검 토 내 용 : | F4: 페블테크 지반보강공법 검토
A5: ○ 검 토 자 : | B5: 검 토 자 : | F5: 토질 및 기초기술사 김선학
B7: 지내력이 부족한 지반에 지반보강 공법으로 페블테크 공법 제안
B9: 기 초 형 식 | G9: =검토서갑지!G9 -> - 지상 150 kN/㎡
B10: 기 초 하 부 지 층 | G10: =검토서갑지!G10 -> - N값 4/30~ 8/30의 실트질 모래
B11: 건 물 규 모 | G11: =검토서갑지!G11 -> - 지상4층
A13: 1. | B13: 개 요
B14: 시추위치도 | P14: 시추주상도
B17: 구 분 | F17: 지충두께 | K17: 지반의 특성 | X17: N치범위
B18: =+입력!A20 -> 매립층 | F18: =+입력!B20 -> 0 | H18: ~ | I18: =+입력!C20 -> 3.5 | K18: =+입력!E20 -> 실트질 모래 | X18: =+입력!G20 -> 4 | Z18: ~ | AA18: =+입력!H20 -> 8
B19: =+입력!A21 -> 퇴적층 | F19: =+입력!B21 -> 3.5 | H19: ~ | I19: =+입력!C21 -> 6.7 | K19: =+입력!E21 -> 실트질 모래 | X19: =+입력!G21 -> 4 | Z19: ~ | AA19: =+입력!H21 -> 11
B20: =+입력!A22 -> 풍화암 | F20: =+입력!B22 -> 6.7 | H20: ~ | I20: =+입력!C22 -> 15 | X20: =+입력!G22 -> 50/7 | Z20: ~ | AA20: =+입력!H22 -> 50/2
B25: * 지반설정정수
B26: 토층 | I26: 단위중량(kN/m3) | N26: 점착력(kN/m2) | S26: 내부마찰각(deg) | X26: 변형계수(kN/m2)
B27: =+입력!A20 -> 매립층 | I27: =+지상1층!K14 -> 18 | N27: =+지상1층!N14 -> 0 | S27: =+지상1층!P14 -> 21 | X27: =+지상1층!U14 -> 9500
B28: =+입력!A21 -> 퇴적층 | I28: =+지상1층!K15 -> 18 | N28: =+지상1층!N15 -> 0 | S28: =+지상1층!P15 -> 23 | X28: =+지상1층!U15 -> 10000
B29: =+입력!A22 -> 풍화암 | I29: =+지상1층!K16 -> 20 | N29: =+지상1층!N16 -> 20 | S29: =+지상1층!P16 -> 30 | X29: =+지상1층!U16 -> 700000

Sheet 지상1층
A1: ▶ | B1: ="페블테크 지내력 검토("&입력!B4&") - ("&AC1&")" -> 페블테크 지내력 검토(전북 전주시 완산구 상림동 596 다세대주택 신축공사) - (지상1층) | AC1: 지상1층 | AF1: =+F5 -> 3.8 | AG1: =+J5 -> 3.9 | AH1: =+N5 -> 0.16 | AI1: =+S228 -> 86.4 | AJ1: =+S496 -> 46.77 | AK1: =+S397+X101 -> 154.8 | AL1: =+S625 -> 22.97 | AT1: 하중조건 250kN/m2 은 PILE기초를 감안하여 적정 하중을 계산하였으며
B2: 1.구조물 기초 일반조건 | AD2: ① | AE2: 도면을 참조하여 시추공번호, 기초폭, 길이, 근입깊이, 설계하중, 지하수위를 기입한다 (B5~X5) | AT2: 구조기술사의 구조안전확인서를 받아 확인해야 합니다.
B3: 검토단면 | F3: 기초형상 | N3: 근입깊이 | R3: 하중조건 | V3: 지하수위 | AD3: ② | AE3: 지반조사서의 지반 층의 구별대로 토층 및 깊이를 기입한다. (D11~F15)
F4: B(m) | J4: L(m) | N4: m | R4: KN/㎡ | V4: m | AD4: ③ | AE4: N치를 고려하여 토층의 단위중량을 기입한다 (K11~K15)
B5: =+입력!D25 -> BH-1 | F5: 3.8 | J5: 3.9 | N5: =+AG43 -> 0.16 | R5: =+입력!D6 -> 150 | V5: =+입력!B25 -> 2.72 | AD5: ④ | AE5: N치를 기반으로 아래 개략산출식으로 점착력 및 내부마찰각을 산출하여 보수적으로 기입한다. (N11~N15, R11~R15)
AD6: ⑤ | AE6: 주상도를 보고 옆의 표에서 깊이별 N치를 기입(BN행)한다.
C7: 기초형식 | G7: =+입력!C8 -> 매트기초 | J7: =+입력!D8 -> THK 500 | AD7: ⑥ | AE7: 입력한 N치를 대입하여 적정 공식을 이용하여 변형계수를 산출한다. (BC행)
AD8: ⑦ | AE8: 2. 원지반 대표상수의 변형계수 값을 기입한다.(U11~U15)
AD9: 심도 | AF9: N치 | AI9: 길 이 (m) | AL9: △Z (m) | AM9: E s | AO9: 분류기호 | AP9: 구분 | AR9: Zp (m)
AM10: (tf/m2) | AU10: ▶ | AV10: 현장 시험 결과와 탄성 계수 (Es, qc는 Kpa 단위임. 1Kpa=0.1tf/㎡)
B11: 2.원지반 현황 | AD11: =+AK11 -> 1 | AF11: 4 | AI11: 0 | AJ11: ~ | AK11: 1 | AL11: =AK11-AI11 -> 1 | AM11: =+IF(AF11>50,1400*AF11,IF(OR(AO11="GW",AO11="GP",AO11="GM",AO11="GC"),1200*(AF11+6),IF(AND(OR(AO11="SC",AO11="SW",AO11="SP",AO11="SM"),AF11>15),1300*AF11,500*(AF11+15)))) -> 9500 | AO11: SM | AP11: 매립층 | AR11: =SUM(AL11)/2 -> 0.5 | AU11: 흙의 종류 | AZ11: S.P.T | BE11: C.P.T
B12: 토층 | D12: 깊이 | H12: 두께 | K12: 단위중량 | N12: 점착력 | P12: 내부마찰각 | S12: 포아송비 | U12: 변형계수 | X12: 비고 | AC12: 분류기호 | AD12: =+AK12 -> 2 | AF12: 5 | AI12: =+AK11 -> 1 | AJ12: ~ | AK12: 2 | AL12: =AK12-AI12 -> 1 | AM12: =+IF(AF12>50,1400*AF12,IF(OR(AO12="GW",AO12="GP",AO12="GM",AO12="GC"),1200*(AF12+6),IF(AND(OR(AO12="SC",AO12="SW",AO12="SP",AO12="SM"),AF12>15),1300*AF12,500*(AF12+15)))) -> 10000 | AO12: SM | AR12: =SUM(AL11)+(AL12/2) -> 1.5 | AU12: 모 래 | AZ12: Es = 766N
H13: m | K13: γt (KN/m3) | N13: C (kN/㎡) | P13: Φ (°) | S13: ν | U13: E (kN/㎡) | AD13: =+AK13 -> 3 | AF13: 5 | AI13: =+AK12 -> 2 | AJ13: ~ | AK13: 3 | AL13: =AK13-AI13 -> 1 | AM13: =+IF(AF13>50,1400*AF13,IF(OR(AO13="GW",AO13="GP",AO13="GM",AO13="GC"),1200*(AF13+6),IF(AND(OR(AO13="SC",AO13="SW",AO13="SP",AO13="SM"),AF13>15),1300*AF13,500*(AF13+15)))) -> 10000 | AO13: SM | AR13: =SUM(AL$11:$AL12)+(AL13/2) -> 2.5 | AZ13: Es = 500( N + 15 ) | BE13: Es = ( 2 ~ 4)qc
B14: =+입력!A20 -> 매립층 | D14: 0 | F14: =+입력!C20 -> 3.5 | H14: =F14-D14 -> 3.5 | K14: =+입력!D20 -> 18 | N14: 0 | P14: 21 | S14: 0.4 | U14: =+AM11 -> 9500 | X14: =+입력!E20 -> 실트질 모래 | AC14: =+입력!F20 -> SM | AD14: =+AK14 -> 4 | AF14: 4 | AI14: =+AK13 -> 3 | AJ14: ~ | AK14: 4 | AL14: =AK14-AI14 -> 1 | AM14: =+IF(AF14>50,1400*AF14,IF(OR(AO14="GW",AO14="GP",AO14="GM",AO14="GC"),1200*(AF14+6),IF(AND(OR(AO14="SC",AO14="SW",AO14="SP",AO14="SM"),AF14>15),1300*AF14,500*(AF14+15)))) -> 9500 | AO14: SM | AR14: =SUM(AL$11:$AL13)+(AL14/2) -> 3.5 | AZ14: Es = 18,000 + 750N | BE14: Es = 2( 1 + Dr2 )qc
B15: =+입력!A21 -> 퇴적층 | D15: =+F14 -> 3.5 | F15: =+입력!C21 -> 6.7 | H15: =F15-D15 -> 3.2 | K15: =+입력!D21 -> 18 | N15: 0 | P15: 23 | S15: 0.38 | U15: =+AM13 -> 10000 | X15: =+입력!E21 -> 실트질 모래 | AC15: =+입력!F21 -> SM | AD15: =+AK15 -> 5 | AF15: 3 | AI15: =+AK14 -> 4 | AJ15: ~ | AK15: 5 | AL15: =AK15-AI15 -> 1 | AM15: =+IF(AF15>50,1400*AF15,IF(OR(AO15="GW",AO15="GP",AO15="GM",AO15="GC"),1200*(AF15+6),IF(AND(OR(AO15="SC",AO15="SW",AO15="SP",AO15="SM"),AF15>15),1300*AF15,500*(AF15+15)))) -> 9000 | AO15: SM | AP15: 퇴적층 | AR15: =SUM(AL$11:$AL14)+(AL15/2) -> 4.5 | AZ15: Es = 450*N + 3900
B16: =+입력!A22 -> 풍화암 | D16: =+F15 -> 6.7 | F16: =+입력!C22 -> 15 | H16: =F16-D16 -> 8.3 | K16: =+입력!D22 -> 20 | N16: 20 | P16: 30 | S16: 0.3 | U16: =+AM20 -> 700000 | AC16: =+입력!F22 -> WR | AD16: =+AK16 -> 6 | AF16: 11 | AI16: =+AK15 -> 5 | AJ16: ~ | AK16: 6 | AL16: =AK16-AI16 -> 1 | AM16: =+IF(AF16>50,1400*AF16,IF(OR(AO16="GW",AO16="GP",AO16="GM",AO16="GC"),1200*(AF16+6),IF(AND(OR(AO16="SC",AO16="SW",AO16="SP",AO16="SM"),AF16>15),1300*AF16,500*(AF16+15)))) -> 13000 | AO16: SM | AR16: =SUM(AL$11:$AL15)+(AL16/2) -> 5.5 | AU16: 점토질 모래 | AZ16: Es = 320( N + 15 ) | BE16: Es = ( 3 ~ 6 )6qc
AC17: =+입력!F23 -> 0 | AD17: =+AK17 -> 7 | AF17: 214 | AI17: =AK16 -> 6 | AJ17: ~ | AK17: 7 | AL17: =AK17-AI17 -> 1 | AM17: =+IF(AF17>50,1400*AF17,IF(OR(AO17="GW",AO17="GP",AO17="GM",AO17="GC"),1200*(AF17+6),IF(AND(OR(AO17="SC",AO17="SW",AO17="SP",AO17="SM"),AF17>15),1300*AF17,500*(AF17+15)))) -> 299600 | AO17: SM | AR17: =SUM(AL$11:$AL16)+(AL17/2) -> 6.5 | AU17: 실트질 모래 | AZ17: Es = 300( N + 6 ) | BE17: Es = 1에서 Pc
AC18: =+입력!F24 -> 0 | AD18: =+AK18 -> 8 | AF18: =50/4*30 -> 375 | AI18: =AK17 -> 7 | AJ18: ~ | AK18: 8 | AL18: =AK18-AI18 -> 1 | AM18: =+IF(AF18>50,1400*AF18,IF(OR(AO18="GW",AO18="GP",AO18="GM",AO18="GC"),1200*(AF18+6),IF(AND(OR(AO18="SC",AO18="SW",AO18="SP",AO18="SM"),AF18>15),1300*AF18,500*(AF18+15)))) -> 525000 | AO18: WR | AP18: 풍화암 | AR18: =SUM(AL$11:$AL17)+(AL18/2) -> 7.5 | AZ18: Es = 530* N + 2400
B19: 합계 | H19: =SUM(H14:J18) -> 15 | AD19: =+AK19 -> 9 | AF19: =50/3*30 -> 500 | AI19: =AK18 -> 8 | AJ19: ~ | AK19: 9 | AL19: =AK19-AI19 -> 1 | AM19: =+IF(AF19>50,1400*AF19,IF(OR(AO19="GW",AO19="GP",AO19="GM",AO19="GC"),1200*(AF19+6),IF(AND(OR(AO19="SC",AO19="SW",AO19="SP",AO19="SM"),AF19>15),1300*AF19,500*(AF19+15)))) -> 700000 | AR19: =SUM(AL$11:$AL18)+(AL19/2) -> 8.5 | AZ19: Es = 400* N
AD20: =+AK20 -> 10 | AF20: =50/3*30 -> 500 | AI20: =AK19 -> 9 | AJ20: ~ | AK20: 10 | AL20: =AK20-AI20 -> 1 | AM20: =+IF(AF20>50,1400*AF20,IF(OR(AO20="GW",AO20="GP",AO20="GM",AO20="GC"),1200*(AF20+6),IF(AND(OR(AO20="SC",AO20="SW",AO20="SP",AO20="SM"),AF20>15),1300*AF20,500*(AF20+15)))) -> 700000 | AR20: =SUM(AL$11:$AL19)+(AL20/2) -> 9.5 | AU20: 조립질 모래 | AZ20: Es = 1,000* N
AD21: =+AK21 -> 11 | AF21: =50/2*30 -> 750 | AI21: =AK20 -> 10 | AJ21: ~ | AK21: 11 | AL21: =AK21-AI21 -> 1 | AM21: =+IF(AF21>50,1400*AF21,IF(OR(AO21="GW",AO21="GP",AO21="GM",AO21="GC"),1200*(AF21+6),IF(AND(OR(AO21="SC",AO21="SW",AO21="SP",AO21="SM"),AF21>15),1300*AF21,500*(AF21+15)))) -> 1050000 | AR21: =SUM(AL$11:$AL20)+(AL21/2) -> 10.5 | AU21: 자갈섞인 모래 | AZ21: Es = 1,200( N + 6 )
AD22: =+AK22 -> 12 | AF22: =50/2*30 -> 750 | AI22: =AK21 -> 11 | AJ22: ~ | AK22: 12 | AL22: =AK22-AI22 -> 1 | AM22: =+IF(AF22>50,1400*AF22,IF(OR(AO22="GW",AO22="GP",AO22="GM",AO22="GC"),1200*(AF22+6),IF(AND(OR(AO22="SC",AO22="SW",AO22="SP",AO22="SM"),AF22>15),1300*AF22,500*(AF22+15)))) -> 1050000 | AR22: =SUM(AL$11:$AL21)+(AL22/2) -> 11.5 | AZ22: Es = (1,200~1500)* N
AD23: =+AK23 -> 13 | AF23: =50/2*30 -> 750 | AI23: =AK22 -> 12 | AJ23: ~ | AK23: 13 | AL23: =AK23-AI23 -> 1 | AM23: =+IF(AF23>50,1400*AF23,IF(OR(AO23="GW",AO23="GP",AO23="GM",AO23="GC"),1200*(AF23+6),IF(AND(OR(AO23="SC",AO23="SW",AO23="SP",AO23="SM"),AF23>15),1300*AF23,500*(AF23+15)))) -> 1050000 | AR23: =SUM(AL$11:$AL22)+(AL23/2) -> 12.5 | AZ23: Es = 1500* N + 3800
AD24: =+AK24 -> 14 | AF24: =50/2*30 -> 750 | AI24: =AK23 -> 13 | AJ24: ~ | AK24: 14 | AL24: =AK24-AI24 -> 1 | AM24: =+IF(AF24>50,1400*AF24,IF(OR(AO24="GW",AO24="GP",AO24="GM",AO24="GC"),1200*(AF24+6),IF(AND(OR(AO24="SC",AO24="SW",AO24="SP",AO24="SM"),AF24>15),1300*AF24,500*(AF24+15)))) -> 1050000 | AR24: =SUM(AL$11:$AL23)+(AL24/2) -> 13.5 | AU24: 연약 점토 | AZ24: Es = 500*( N + 15) | BE24: Es = ( 6 ~ 8 )qc
AD25: =+AK25 -> 15 | AF25: =50/2*30 -> 750 | AI25: =AK24 -> 14 | AJ25: ~ | AK25: 15 | AL25: =AK25-AI25 -> 1 | AM25: =+IF(AF25>50,1400*AF25,IF(OR(AO25="GW",AO25="GP",AO25="GM",AO25="GC"),1200*(AF25+6),IF(AND(OR(AO25="SC",AO25="SW",AO25="SP",AO25="SM"),AF25>15),1300*AF25,500*(AF25+15)))) -> 1050000 | AR25: =SUM(AL$11:$AL24)+(AL25/2) -> 14.5 | AU25: 점 토 | AZ25: Ip > 30, 또는 유기질 | BE25: Es = ( 100 ~ 500 )Su
AD26: =+AK26 -> 16 | AF26: =50/2*30 -> 750 | AI26: =AK25 -> 15 | AJ26: ~ | AK26: 16 | AL26: =AK26-AI26 -> 1 | AM26: =+IF(AF26>50,1400*AF26,IF(OR(AO26="GW",AO26="GP",AO26="GM",AO26="GC"),1200*(AF26+6),IF(AND(OR(AO26="SC",AO26="SW",AO26="SP",AO26="SM"),AF26>15),1300*AF26,500*(AF26+15)))) -> 1050000 | AR26: =SUM(AL$11:$AL25)+(AL26/2) -> 15.5 | AZ26: Ip = ( 2 ~ 4 )qc | BE26: Es = ( 500 ~ 1,500 )Su
AD27: =+AK27 -> 17 | AF27: =50/2*30 -> 750 | AI27: =AK26 -> 16 | AJ27: ~ | AK27: 17 | AL27: =AK27-AI27 -> 1 | AM27: =+IF(AF27>50,1400*AF27,IF(OR(AO27="GW",AO27="GP",AO27="GM",AO27="GC"),1200*(AF27+6),IF(AND(OR(AO27="SC",AO27="SW",AO27="SP",AO27="SM"),AF27>15),1300*AF27,500*(AF27+15)))) -> 1050000 | AR27: =SUM(AL$11:$AL26)+(AL27/2) -> 16.5 | AU27: (Su:비배수전단강도) | AZ27: 1 < O.C.R < 2 | BE27: Es = (800 ~ 1,200)Su
AD28: =+AK28 -> 18 | AF28: =50/2*30 -> 750 | AI28: =AK27 -> 17 | AJ28: ~ | AK28: 18 | AL28: =AK28-AI28 -> 1 | AM28: =+IF(AF28>50,1400*AF28,IF(OR(AO28="GW",AO28="GP",AO28="GM",AO28="GC"),1200*(AF28+6),IF(AND(OR(AO28="SC",AO28="SW",AO28="SP",AO28="SM"),AF28>15),1300*AF28,500*(AF28+15)))) -> 1050000 | AR28: =SUM(AL$11:$AL27)+(AL28/2) -> 17.5 | AZ28: O.C.R > 2 | BE28: Es = (1,500 ~ 2,000)Su
AD29: =+AK29 -> 19 | AF29: =50/2*30 -> 750 | AI29: =AK28 -> 18 | AJ29: ~ | AK29: 19 | AL29: =AK29-AI29 -> 1 | AM29: =+IF(AF29>50,1400*AF29,IF(OR(AO29="GW",AO29="GP",AO29="GM",AO29="GC"),1200*(AF29+6),IF(AND(OR(AO29="SC",AO29="SW",AO29="SP",AO29="SM"),AF29>15),1300*AF29,500*(AF29+15)))) -> 1050000 | AR29: =SUM(AL$11:$AL28)+(AL29/2) -> 18.5
AD30: =+AK30 -> 20 | AF30: =50/2*30 -> 750 | AI30: =AK29 -> 19 | AJ30: ~ | AK30: 20 | AL30: =AK30-AI30 -> 1 | AM30: =+IF(AF30>50,1400*AF30,IF(OR(AO30="GW",AO30="GP",AO30="GM",AO30="GC"),1200*(AF30+6),IF(AND(OR(AO30="SC",AO30="SW",AO30="SP",AO30="SM"),AF30>15),1300*AF30,500*(AF30+15)))) -> 1050000 | AR30: =SUM(AL$11:$AL29)+(AL30/2) -> 19.5
AD31: =+AK31 -> 21 | AF31: =50/2*30 -> 750 | AI31: =AK30 -> 20 | AJ31: ~ | AK31: 21 | AL31: =AK31-AI31 -> 1 | AM31: =+IF(AF31>50,1400*AF31,IF(OR(AO31="GW",AO31="GP",AO31="GM",AO31="GC"),1200*(AF31+6),IF(AND(OR(AO31="SC",AO31="SW",AO31="SP",AO31="SM"),AF31>15),1300*AF31,500*(AF31+15)))) -> 1050000 | AR31: =SUM(AL$11:$AL30)+(AL31/2) -> 20.5
AD32: =+AK32 -> 22 | AF32: =50/2*30 -> 750 | AI32: =AK31 -> 21 | AJ32: ~ | AK32: 22 | AL32: =AK32-AI32 -> 1 | AM32: =+IF(AF32>50,1400*AF32,IF(OR(AO32="GW",AO32="GP",AO32="GM",AO32="GC"),1200*(AF32+6),IF(AND(OR(AO32="SC",AO32="SW",AO32="SP",AO32="SM"),AF32>15),1300*AF32,500*(AF32+15)))) -> 1050000 | AR32: =SUM(AL$11:$AL31)+(AL32/2) -> 21.5
AD33: =+AK33 -> 23 | AF33: =50/2*30 -> 750 | AI33: =AK32 -> 22 | AJ33: ~ | AK33: 23 | AL33: =AK33-AI33 -> 1 | AM33: =+IF(AF33>50,1400*AF33,IF(OR(AO33="GW",AO33="GP",AO33="GM",AO33="GC"),1200*(AF33+6),IF(AND(OR(AO33="SC",AO33="SW",AO33="SP",AO33="SM"),AF33>15),1300*AF33,500*(AF33+15)))) -> 1050000 | AR33: =SUM(AL$11:$AL32)+(AL33/2) -> 22.5
AD34: =+AK34 -> 24 | AF34: =50/2*30 -> 750 | AI34: =AK33 -> 23 | AJ34: ~ | AK34: 24 | AL34: =AK34-AI34 -> 1 | AM34: =+IF(AF34>50,1400*AF34,IF(OR(AO34="GW",AO34="GP",AO34="GM",AO34="GC"),1200*(AF34+6),IF(AND(OR(AO34="SC",AO34="SW",AO34="SP",AO34="SM"),AF34>15),1300*AF34,500*(AF34+15)))) -> 1050000 | AR34: =SUM(AL$11:$AL33)+(AL34/2) -> 23.5
AD35: =+AK35 -> 25 | AF35: =50/2*30 -> 750 | AI35: =AK34 -> 24 | AJ35: ~ | AK35: 25 | AL35: =AK35-AI35 -> 1 | AM35: =+IF(AF35>50,1400*AF35,IF(OR(AO35="GW",AO35="GP",AO35="GM",AO35="GC"),1200*(AF35+6),IF(AND(OR(AO35="SC",AO35="SW",AO35="SP",AO35="SM"),AF35>15),1300*AF35,500*(AF35+15)))) -> 1050000 | AR35: =SUM(AL$11:$AL34)+(AL35/2) -> 24.5
AD36: =+AK36 -> 26 | AF36: =50/2*30 -> 750 | AI36: =AK35 -> 25 | AJ36: ~ | AK36: 26 | AL36: =AK36-AI36 -> 1 | AM36: =+IF(AF36>50,1400*AF36,IF(OR(AO36="GW",AO36="GP",AO36="GM",AO36="GC"),1200*(AF36+6),IF(AND(OR(AO36="SC",AO36="SW",AO36="SP",AO36="SM"),AF36>15),1300*AF36,500*(AF36+15)))) -> 1050000 | AR36: =SUM(AL$11:$AL35)+(AL36/2) -> 25.5
AD37: =+AK37 -> 27 | AF37: =50/2*30 -> 750 | AI37: =AK36 -> 26 | AJ37: ~ | AK37: 27 | AL37: =AK37-AI37 -> 1 | AM37: =+IF(AF37>50,1400*AF37,IF(OR(AO37="GW",AO37="GP",AO37="GM",AO37="GC"),1200*(AF37+6),IF(AND(OR(AO37="SC",AO37="SW",AO37="SP",AO37="SM"),AF37>15),1300*AF37,500*(AF37+15)))) -> 1050000 | AR37: =SUM(AL$11:$AL36)+(AL37/2) -> 26.5
AD39: BH-1 EL | AG39: 0 | AI39: 주상도상의 EL | AL39: 주상도의 현황레벨과 마감레벨이 다를 경우 절토 도는 성토해야하는데
AD40: GL 0 | AG40: 0 | AI40: 절토, 성토, 마감레벨 | AL40: 그럴 경우 주상도상의 근입깊이와 마감후의 근입깊이가 다름
AD41: 기초깊이 | AG41: 0.16 | AI41: GL 0기준 깊이 | AL41: 기초두께는 마감레벨에서의 근입깊이임
...

Sheet PIT
A1: ▶ | B1: ="페블테크 지내력 검토("&입력!B4&") - ("&AC1&")" -> 페블테크 지내력 검토(전북 전주시 완산구 상림동 596 다세대주택 신축공사) - (지상1층) | AC1: 지상1층 | AF1: =+F5 -> 1.85 | AG1: =+J5 -> 2.5 | AH1: =+N5 -> 1.16 | AI1: =+S228 -> 87.8 | AJ1: =+S496 -> 23.91 | AK1: =+S397+X101 -> 181.3 | AL1: =+S625 -> 5.53 | AT1: 하중조건 250kN/m2 은 PILE기초를 감안하여 적정 하중을 계산하였으며
B2: 1.구조물 기초 일반조건 | AD2: ① | AE2: 도면을 참조하여 시추공번호, 기초폭, 길이, 근입깊이, 설계하중, 지하수위를 기입한다 (B5~X5) | AT2: 구조기술사의 구조안전확인서를 받아 확인해야 합니다.
B3: 검토단면 | F3: 기초형상 | N3: 근입깊이 | R3: 하중조건 | V3: 지하수위 | AD3: ② | AE3: 지반조사서의 지반 층의 구별대로 토층 및 깊이를 기입한다. (D11~F15)
F4: B(m) | J4: L(m) | N4: m | R4: KN/㎡ | V4: m | AD4: ③ | AE4: N치를 고려하여 토층의 단위중량을 기입한다 (K11~K15)
B5: =+입력!D25 -> BH-1 | F5: 1.85 | J5: 2.5 | N5: =+AG43 -> 1.16 | R5: =+입력!D6 -> 150 | V5: =+입력!B25 -> 2.72 | AD5: ④ | AE5: N치를 기반으로 아래 개략산출식으로 점착력 및 내부마찰각을 산출하여 보수적으로 기입한다. (N11~N15, R11~R15)
AD6: ⑤ | AE6: 주상도를 보고 옆의 표에서 깊이별 N치를 기입(BN행)한다.
C7: 기초형식 | G7: =+입력!C8 -> 매트기초 | J7: =+입력!D8 -> THK 500 | AD7: ⑥ | AE7: 입력한 N치를 대입하여 적정 공식을 이용하여 변형계수를 산출한다. (BC행)
AD8: ⑦ | AE8: 2. 원지반 대표상수의 변형계수 값을 기입한다.(U11~U15)
AD9: 심도 | AF9: N치 | AI9: 길 이 (m) | AL9: △Z (m) | AM9: E s | AO9: 분류기호 | AP9: 구분 | AR9: Zp (m)
AM10: (tf/m2) | AU10: ▶ | AV10: 현장 시험 결과와 탄성 계수 (Es, qc는 Kpa 단위임. 1Kpa=0.1tf/㎡)
B11: 2.원지반 현황 | AD11: =+AK11 -> 1 | AF11: 4 | AI11: 0 | AJ11: ~ | AK11: 1 | AL11: =AK11-AI11 -> 1 | AM11: =+IF(AF11>50,1400*AF11,IF(OR(AO11="GW",AO11="GP",AO11="GM",AO11="GC"),1200*(AF11+6),IF(AND(OR(AO11="SC",AO11="SW",AO11="SP",AO11="SM"),AF11>15),1300*AF11,500*(AF11+15)))) -> 9500 | AO11: SC | AP11: 매립층 | AR11: =SUM(AL11)/2 -> 0.5 | AU11: 흙의 종류 | AZ11: S.P.T | BE11: C.P.T
B12: 토층 | D12: 깊이 | H12: 두께 | K12: 단위중량 | N12: 점착력 | P12: 내부마찰각 | S12: 포아송비 | U12: 변형계수 | X12: 비고 | AC12: 분류기호 | AD12: =+AK12 -> 2 | AF12: 5 | AI12: =+AK11 -> 1 | AJ12: ~ | AK12: 2 | AL12: =AK12-AI12 -> 1 | AM12: =+IF(AF12>50,1400*AF12,IF(OR(AO12="GW",AO12="GP",AO12="GM",AO12="GC"),1200*(AF12+6),IF(AND(OR(AO12="SC",AO12="SW",AO12="SP",AO12="SM"),AF12>15),1300*AF12,500*(AF12+15)))) -> 10000 | AO12: SC | AR12: =SUM(AL11)+(AL12/2) -> 1.5 | AU12: 모 래 | AZ12: Es = 766N
H13: m | K13: γt (KN/m3) | N13: C (kN/㎡) | P13: Φ (°) | S13: ν | U13: E (kN/㎡) | AD13: =+AK13 -> 3 | AF13: 5 | AI13: =+AK12 -> 2 | AJ13: ~ | AK13: 3 | AL13: =AK13-AI13 -> 1 | AM13: =+IF(AF13>50,1400*AF13,IF(OR(AO13="GW",AO13="GP",AO13="GM",AO13="GC"),1200*(AF13+6),IF(AND(OR(AO13="SC",AO13="SW",AO13="SP",AO13="SM"),AF13>15),1300*AF13,500*(AF13+15)))) -> 10000 | AO13: SC | AR13: =SUM(AL$11:$AL12)+(AL13/2) -> 2.5 | AZ13: Es = 500( N + 15 ) | BE13: Es = ( 2 ~ 4)qc
B14: =+입력!A20 -> 매립층 | D14: 0 | F14: =+입력!C20 -> 3.5 | H14: =F14-D14 -> 3.5 | K14: =+입력!D20 -> 18 | N14: 0 | P14: 21 | S14: 0.4 | U14: =+AM11 -> 9500 | X14: =+입력!E20 -> 실트질 모래 | AC14: =+입력!F20 -> SM | AD14: =+AK14 -> 4 | AF14: 4 | AI14: =+AK13 -> 3 | AJ14: ~ | AK14: 4 | AL14: =AK14-AI14 -> 1 | AM14: =+IF(AF14>50,1400*AF14,IF(OR(AO14="GW",AO14="GP",AO14="GM",AO14="GC"),1200*(AF14+6),IF(AND(OR(AO14="SC",AO14="SW",AO14="SP",AO14="SM"),AF14>15),1300*AF14,500*(AF14+15)))) -> 9500 | AO14: SC | AR14: =SUM(AL$11:$AL13)+(AL14/2) -> 3.5 | AZ14: Es = 18,000 + 750N | BE14: Es = 2( 1 + Dr2 )qc
B15: =+입력!A21 -> 퇴적층 | D15: =+F14 -> 3.5 | F15: =+입력!C21 -> 6.7 | H15: =F15-D15 -> 3.2 | K15: =+입력!D21 -> 18 | N15: 0 | P15: 23 | S15: 0.38 | U15: =+AM13 -> 10000 | X15: =+입력!E21 -> 실트질 모래 | AC15: =+입력!F21 -> SM | AD15: =+AK15 -> 5 | AF15: 3 | AI15: =+AK14 -> 4 | AJ15: ~ | AK15: 5 | AL15: =AK15-AI15 -> 1 | AM15: =+IF(AF15>50,1400*AF15,IF(OR(AO15="GW",AO15="GP",AO15="GM",AO15="GC"),1200*(AF15+6),IF(AND(OR(AO15="SC",AO15="SW",AO15="SP",AO15="SM"),AF15>15),1300*AF15,500*(AF15+15)))) -> 9000 | AO15: SC | AP15: 퇴적층 | AR15: =SUM(AL$11:$AL14)+(AL15/2) -> 4.5 | AZ15: Es = 450*N + 3900
B16: =+입력!A22 -> 풍화암 | D16: =+F15 -> 6.7 | F16: =+입력!C22 -> 15 | H16: =F16-D16 -> 8.3 | K16: =+입력!D22 -> 20 | N16: 20 | P16: 30 | S16: 0.3 | U16: =+AM20 -> 700000 | AC16: =+입력!F22 -> WR | AD16: =+AK16 -> 6 | AF16: 11 | AI16: =+AK15 -> 5 | AJ16: ~ | AK16: 6 | AL16: =AK16-AI16 -> 1 | AM16: =+IF(AF16>50,1400*AF16,IF(OR(AO16="GW",AO16="GP",AO16="GM",AO16="GC"),1200*(AF16+6),IF(AND(OR(AO16="SC",AO16="SW",AO16="SP",AO16="SM"),AF16>15),1300*AF16,500*(AF16+15)))) -> 13000 | AO16: SC | AR16: =SUM(AL$11:$AL15)+(AL16/2) -> 5.5 | AU16: 점토질 모래 | AZ16: Es = 320( N + 15 ) | BE16: Es = ( 3 ~ 6 )6qc
AC17: =+입력!F23 -> 0 | AD17: =+AK17 -> 7 | AF17: 214 | AI17: =AK16 -> 6 | AJ17: ~ | AK17: 7 | AL17: =AK17-AI17 -> 1 | AM17: =+IF(AF17>50,1400*AF17,IF(OR(AO17="GW",AO17="GP",AO17="GM",AO17="GC"),1200*(AF17+6),IF(AND(OR(AO17="SC",AO17="SW",AO17="SP",AO17="SM"),AF17>15),1300*AF17,500*(AF17+15)))) -> 299600 | AO17: SC | AR17: =SUM(AL$11:$AL16)+(AL17/2) -> 6.5 | AU17: 실트질 모래 | AZ17: Es = 300( N + 6 ) | BE17: Es = 1에서 Pc
AC18: =+입력!F24 -> 0 | AD18: =+AK18 -> 8 | AF18: =50/4*30 -> 375 | AI18: =AK17 -> 7 | AJ18: ~ | AK18: 8 | AL18: =AK18-AI18 -> 1 | AM18: =+IF(AF18>50,1400*AF18,IF(OR(AO18="GW",AO18="GP",AO18="GM",AO18="GC"),1200*(AF18+6),IF(AND(OR(AO18="SC",AO18="SW",AO18="SP",AO18="SM"),AF18>15),1300*AF18,500*(AF18+15)))) -> 525000 | AO18: WR | AP18: 풍화암 | AR18: =SUM(AL$11:$AL17)+(AL18/2) -> 7.5 | AZ18: Es = 530* N + 2400
B19: 합계 | H19: =SUM(H14:J18) -> 15 | AD19: =+AK19 -> 9 | AF19: =50/3*30 -> 500 | AI19: =AK18 -> 8 | AJ19: ~ | AK19: 9 | AL19: =AK19-AI19 -> 1 | AM19: =+IF(AF19>50,1400*AF19,IF(OR(AO19="GW",AO19="GP",AO19="GM",AO19="GC"),1200*(AF19+6),IF(AND(OR(AO19="SC",AO19="SW",AO19="SP",AO19="SM"),AF19>15),1300*AF19,500*(AF19+15)))) -> 700000 | AR19: =SUM(AL$11:$AL18)+(AL19/2) -> 8.5 | AZ19: Es = 400* N
AD20: =+AK20 -> 10 | AF20: =50/3*30 -> 500 | AI20: =AK19 -> 9 | AJ20: ~ | AK20: 10 | AL20: =AK20-AI20 -> 1 | AM20: =+IF(AF20>50,1400*AF20,IF(OR(AO20="GW",AO20="GP",AO20="GM",AO20="GC"),1200*(AF20+6),IF(AND(OR(AO20="SC",AO20="SW",AO20="SP",AO20="SM"),AF20>15),1300*AF20,500*(AF20+15)))) -> 700000 | AR20: =SUM(AL$11:$AL19)+(AL20/2) -> 9.5 | AU20: 조립질 모래 | AZ20: Es = 1,000* N
AD21: =+AK21 -> 11 | AF21: =50/2*30 -> 750 | AI21: =AK20 -> 10 | AJ21: ~ | AK21: 11 | AL21: =AK21-AI21 -> 1 | AM21: =+IF(AF21>50,1400*AF21,IF(OR(AO21="GW",AO21="GP",AO21="GM",AO21="GC"),1200*(AF21+6),IF(AND(OR(AO21="SC",AO21="SW",AO21="SP",AO21="SM"),AF21>15),1300*AF21,500*(AF21+15)))) -> 1050000 | AR21: =SUM(AL$11:$AL20)+(AL21/2) -> 10.5 | AU21: 자갈섞인 모래 | AZ21: Es = 1,200( N + 6 )
AD22: =+AK22 -> 12 | AF22: =50/2*30 -> 750 | AI22: =AK21 -> 11 | AJ22: ~ | AK22: 12 | AL22: =AK22-AI22 -> 1 | AM22: =+IF(AF22>50,1400*AF22,IF(OR(AO22="GW",AO22="GP",AO22="GM",AO22="GC"),1200*(AF22+6),IF(AND(OR(AO22="SC",AO22="SW",AO22="SP",AO22="SM"),AF22>15),1300*AF22,500*(AF22+15)))) -> 1050000 | AR22: =SUM(AL$11:$AL21)+(AL22/2) -> 11.5 | AZ22: Es = (1,200~1500)* N
AD23: =+AK23 -> 13 | AF23: =50/2*30 -> 750 | AI23: =AK22 -> 12 | AJ23: ~ | AK23: 13 | AL23: =AK23-AI23 -> 1 | AM23: =+IF(AF23>50,1400*AF23,IF(OR(AO23="GW",AO23="GP",AO23="GM",AO23="GC"),1200*(AF23+6),IF(AND(OR(AO23="SC",AO23="SW",AO23="SP",AO23="SM"),AF23>15),1300*AF23,500*(AF23+15)))) -> 1050000 | AR23: =SUM(AL$11:$AL22)+(AL23/2) -> 12.5 | AZ23: Es = 1500* N + 3800
AD24: =+AK24 -> 14 | AF24: =50/2*30 -> 750 | AI24: =AK23 -> 13 | AJ24: ~ | AK24: 14 | AL24: =AK24-AI24 -> 1 | AM24: =+IF(AF24>50,1400*AF24,IF(OR(AO24="GW",AO24="GP",AO24="GM",AO24="GC"),1200*(AF24+6),IF(AND(OR(AO24="SC",AO24="SW",AO24="SP",AO24="SM"),AF24>15),1300*AF24,500*(AF24+15)))) -> 1050000 | AR24: =SUM(AL$11:$AL23)+(AL24/2) -> 13.5 | AU24: 연약 점토 | AZ24: Es = 500*( N + 15) | BE24: Es = ( 6 ~ 8 )qc
AD25: =+AK25 -> 15 | AF25: =50/2*30 -> 750 | AI25: =AK24 -> 14 | AJ25: ~ | AK25: 15 | AL25: =AK25-AI25 -> 1 | AM25: =+IF(AF25>50,1400*AF25,IF(OR(AO25="GW",AO25="GP",AO25="GM",AO25="GC"),1200*(AF25+6),IF(AND(OR(AO25="SC",AO25="SW",AO25="SP",AO25="SM"),AF25>15),1300*AF25,500*(AF25+15)))) -> 1050000 | AR25: =SUM(AL$11:$AL24)+(AL25/2) -> 14.5 | AU25: 점 토 | AZ25: Ip > 30, 또는 유기질 | BE25: Es = ( 100 ~ 500 )Su
AD26: =+AK26 -> 16 | AF26: =50/2*30 -> 750 | AI26: =AK25 -> 15 | AJ26: ~ | AK26: 16 | AL26: =AK26-AI26 -> 1 | AM26: =+IF(AF26>50,1400*AF26,IF(OR(AO26="GW",AO26="GP",AO26="GM",AO26="GC"),1200*(AF26+6),IF(AND(OR(AO26="SC",AO26="SW",AO26="SP",AO26="SM"),AF26>15),1300*AF26,500*(AF26+15)))) -> 1050000 | AR26: =SUM(AL$11:$AL25)+(AL26/2) -> 15.5 | AZ26: Ip = ( 2 ~ 4 )qc | BE26: Es = ( 500 ~ 1,500 )Su
AD27: =+AK27 -> 17 | AF27: =50/2*30 -> 750 | AI27: =AK26 -> 16 | AJ27: ~ | AK27: 17 | AL27: =AK27-AI27 -> 1 | AM27: =+IF(AF27>50,1400*AF27,IF(OR(AO27="GW",AO27="GP",AO27="GM",AO27="GC"),1200*(AF27+6),IF(AND(OR(AO27="SC",AO27="SW",AO27="SP",AO27="SM"),AF27>15),1300*AF27,500*(AF27+15)))) -> 1050000 | AR27: =SUM(AL$11:$AL26)+(AL27/2) -> 16.5 | AU27: (Su:비배수전단강도) | AZ27: 1 < O.C.R < 2 | BE27: Es = (800 ~ 1,200)Su
AD28: =+AK28 -> 18 | AF28: =50/2*30 -> 750 | AI28: =AK27 -> 17 | AJ28: ~ | AK28: 18 | AL28: =AK28-AI28 -> 1 | AM28: =+IF(AF28>50,1400*AF28,IF(OR(AO28="GW",AO28="GP",AO28="GM",AO28="GC"),1200*(AF28+6),IF(AND(OR(AO28="SC",AO28="SW",AO28="SP",AO28="SM"),AF28>15),1300*AF28,500*(AF28+15)))) -> 1050000 | AR28: =SUM(AL$11:$AL27)+(AL28/2) -> 17.5 | AZ28: O.C.R > 2 | BE28: Es = (1,500 ~ 2,000)Su
AD29: =+AK29 -> 19 | AF29: =50/2*30 -> 750 | AI29: =AK28 -> 18 | AJ29: ~ | AK29: 19 | AL29: =AK29-AI29 -> 1 | AM29: =+IF(AF29>50,1400*AF29,IF(OR(AO29="GW",AO29="GP",AO29="GM",AO29="GC"),1200*(AF29+6),IF(AND(OR(AO29="SC",AO29="SW",AO29="SP",AO29="SM"),AF29>15),1300*AF29,500*(AF29+15)))) -> 1050000 | AR29: =SUM(AL$11:$AL28)+(AL29/2) -> 18.5
AD30: =+AK30 -> 20 | AF30: =50/2*30 -> 750 | AI30: =AK29 -> 19 | AJ30: ~ | AK30: 20 | AL30: =AK30-AI30 -> 1 | AM30: =+IF(AF30>50,1400*AF30,IF(OR(AO30="GW",AO30="GP",AO30="GM",AO30="GC"),1200*(AF30+6),IF(AND(OR(AO30="SC",AO30="SW",AO30="SP",AO30="SM"),AF30>15),1300*AF30,500*(AF30+15)))) -> 1050000 | AR30: =SUM(AL$11:$AL29)+(AL30/2) -> 19.5
AD31: =+AK31 -> 21 | AF31: =50/2*30 -> 750 | AI31: =AK30 -> 20 | AJ31: ~ | AK31: 21 | AL31: =AK31-AI31 -> 1 | AM31: =+IF(AF31>50,1400*AF31,IF(OR(AO31="GW",AO31="GP",AO31="GM",AO31="GC"),1200*(AF31+6),IF(AND(OR(AO31="SC",AO31="SW",AO31="SP",AO31="SM"),AF31>15),1300*AF31,500*(AF31+15)))) -> 1050000 | AR31: =SUM(AL$11:$AL30)+(AL31/2) -> 20.5
AD32: =+AK32 -> 22 | AF32: =50/2*30 -> 750 | AI32: =AK31 -> 21 | AJ32: ~ | AK32: 22 | AL32: =AK32-AI32 -> 1 | AM32: =+IF(AF32>50,1400*AF32,IF(OR(AO32="GW",AO32="GP",AO32="GM",AO32="GC"),1200*(AF32+6),IF(AND(OR(AO32="SC",AO32="SW",AO32="SP",AO32="SM"),AF32>15),1300*AF32,500*(AF32+15)))) -> 1050000 | AR32: =SUM(AL$11:$AL31)+(AL32/2) -> 21.5
AD33: =+AK33 -> 23 | AF33: =50/2*30 -> 750 | AI33: =AK32 -> 22 | AJ33: ~ | AK33: 23 | AL33: =AK33-AI33 -> 1 | AM33: =+IF(AF33>50,1400*AF33,IF(OR(AO33="GW",AO33="GP",AO33="GM",AO33="GC"),1200*(AF33+6),IF(AND(OR(AO33="SC",AO33="SW",AO33="SP",AO33="SM"),AF33>15),1300*AF33,500*(AF33+15)))) -> 1050000 | AR33: =SUM(AL$11:$AL32)+(AL33/2) -> 22.5
AD34: =+AK34 -> 24 | AF34: =50/2*30 -> 750 | AI34: =AK33 -> 23 | AJ34: ~ | AK34: 24 | AL34: =AK34-AI34 -> 1 | AM34: =+IF(AF34>50,1400*AF34,IF(OR(AO34="GW",AO34="GP",AO34="GM",AO34="GC"),1200*(AF34+6),IF(AND(OR(AO34="SC",AO34="SW",AO34="SP",AO34="SM"),AF34>15),1300*AF34,500*(AF34+15)))) -> 1050000 | AR34: =SUM(AL$11:$AL33)+(AL34/2) -> 23.5
AD35: =+AK35 -> 25 | AF35: =50/2*30 -> 750 | AI35: =AK34 -> 24 | AJ35: ~ | AK35: 25 | AL35: =AK35-AI35 -> 1 | AM35: =+IF(AF35>50,1400*AF35,IF(OR(AO35="GW",AO35="GP",AO35="GM",AO35="GC"),1200*(AF35+6),IF(AND(OR(AO35="SC",AO35="SW",AO35="SP",AO35="SM"),AF35>15),1300*AF35,500*(AF35+15)))) -> 1050000 | AR35: =SUM(AL$11:$AL34)+(AL35/2) -> 24.5
AD36: =+AK36 -> 26 | AF36: =50/2*30 -> 750 | AI36: =AK35 -> 25 | AJ36: ~ | AK36: 26 | AL36: =AK36-AI36 -> 1 | AM36: =+IF(AF36>50,1400*AF36,IF(OR(AO36="GW",AO36="GP",AO36="GM",AO36="GC"),1200*(AF36+6),IF(AND(OR(AO36="SC",AO36="SW",AO36="SP",AO36="SM"),AF36>15),1300*AF36,500*(AF36+15)))) -> 1050000 | AR36: =SUM(AL$11:$AL35)+(AL36/2) -> 25.5
AD37: =+AK37 -> 27 | AF37: =50/2*30 -> 750 | AI37: =AK36 -> 26 | AJ37: ~ | AK37: 27 | AL37: =AK37-AI37 -> 1 | AM37: =+IF(AF37>50,1400*AF37,IF(OR(AO37="GW",AO37="GP",AO37="GM",AO37="GC"),1200*(AF37+6),IF(AND(OR(AO37="SC",AO37="SW",AO37="SP",AO37="SM"),AF37>15),1300*AF37,500*(AF37+15)))) -> 1050000 | AR37: =SUM(AL$11:$AL36)+(AL37/2) -> 26.5
AD39: BH-1 EL | AG39: 0 | AI39: 주상도상의 EL | AL39: 주상도의 현황레벨과 마감레벨이 다를 경우 절토 도는 성토해야하는데
AD40: GL 0 | AG40: 0 | AI40: 절토, 성토, 마감레벨 | AL40: 그럴 경우 주상도상의 근입깊이와 마감후의 근입깊이가 다름
AD41: 기초깊이 | AG41: =0.16+1 -> 1.16 | AI41: GL 0기준 깊이 | AL41: 기초두께는 마감레벨에서의 근입깊이임
...

Sheet 기초안정성확인서
A3: 1. | B3: 공사명 | G3: : | H3: =입력!B4 -> 전북 전주시 완산구 상림동 596 다세대주택 신축공사
A4: 2. | B4: 대지위치 | G4: : | H4: =입력!B2 -> 0
A5: 3. | B5: 건물규모 | G5: : | H5: =입력!C14 -> 지상4층
A6: 4. | B6: 적용내용 | G6: : | H6: - | I6: 기초형식 | M6: : | N6: =입력!D8 &" ("&입력!D6&" kN/㎡)" -> THK 500 (150 kN/㎡)
H7: - | I7: 기초하부 지층 | M7: : | N7: =입력!A20&" ~ "&입력!A23&" "&"("&입력!E20&")" -> 매립층 ~ (실트질 모래)
H8: - | I8: 지반보강 | M8: : | N8: ="페블테크 "&입력!B16&"mm + PETMAT "&입력!C16&"겹" -> 페블테크 500mm + PETMAT 1겹
A9: 5. | B9: 기초안정성확인내용 | G9: :
B10: (1) 기초지반 현황
B11: 지반조사 지층단면 | P11: 페블테크 보강
B13: =" - N값 "&입력!C13&"~"&입력!D13&"의"&N7&"으로 구성되어 있음" -> - N값 4/30~8/30의매립층 ~ (실트질 모래)으로 구성되어 있음
B14: =" - 공내수위는 GL-"&입력!B25&"m 내 기초저면에 위치함" -> - 공내수위는 GL-2.72m 내 기초저면에 위치함
B16: (2) 원지반 기초 안정성
B17: =" - 기초하부 지반이 "&입력!E22&"로 구성된 "&입력!A22&"층으로, 설계하중 "&입력!D6&" kN/㎡에 대한 기초안정성은 확보할 수 없을 것 으로 " -> - 기초하부 지반이 로 구성된 풍화암층으로, 설계하중 150 kN/㎡에 대한 기초안정성은 확보할 수 없을 것 으로
B18: 판단됨
B20: (3) 페블테크 공법 적용시 기초 안정성
B21: =" - 페블테크 공법의 다양한 시공 사례와 해당 부지의 지반 조건을 고려할 때 페블테크 보강하여 설계하중 "&입력!D6&" kN/㎡에" -> - 페블테크 공법의 다양한 시공 사례와 해당 부지의 지반 조건을 고려할 때 페블테크 보강하여 설계하중 150 kN/㎡에
B22: 대한 기초 안정성은 충분히 만족함
B24: =" - 특히, 원 지반과 페블테크간의 강성차로 상부하중을 분배시켜 원지반에 전달되는 하중을 감소시키는 페블테크의" -> - 특히, 원 지반과 페블테크간의 강성차로 상부하중을 분배시켜 원지반에 전달되는 하중을 감소시키는 페블테크의
B25: 메커니즘은 침하량을 효과적으로 감소 시킬수 있음
B27: =" - 지반보강에 대한 품질관리를 위해 페블테크 보강면에서 평판재하시험을 시행하여 허용지내력 이상을 확인하여야 함" -> - 지반보강에 대한 품질관리를 위해 페블테크 보강면에서 평판재하시험을 시행하여 허용지내력 이상을 확인하여야 함
A29: =제출문!A26 -> 2025-08
B31: * 기초 하부 지반을 고려하여 페블테크 지반 보강시 기초 안정성을 확인함.
U34: 토질 및 기초기술사
U35: 김 선 학 (인)

Sheet B-7.4(무보강)
A1: ▶ | B1: 페블테크 지내력 검토(KDN충북사업처) - 지하층
B2: 1.구조물 기초 일반조건 | AD2: ① | AE2: 도면을 참조하여 시추공번호, 기초폭, 길이, 근입깊이, 설계하중, 지하수위를 기입한다 (B5~X5)
B3: 검토단면 | G3: 기초형상 | O3: 근입깊이 | S3: 하중조건 | X3: 지하수위 | AD3: ② | AE3: 지반조사서의 지반 층의 구별대로 토층 및 깊이를 기입한다. (D11~F15) | BM3: N치-주상도 입력
G4: B(m) | K4: L(m) | O4: m | S4: KN/㎡ | X4: m | AD4: ③ | AE4: N치를 고려하여 토층의 단위중량을 기입한다 (K11~K15) | AX4: 길 이 (m) | BA4: △Z (m) | BC4: E s | BD4: 평균 I z | BE4: I z | BF4: ㆍ△Z | BG4: I z | BH4: ㆍ△Z | BJ4: Zp (m) | BL4: 심도 | BN4: N치
B5: BH-2 | G5: 8.4 | K5: 8.8 | O5: 7.4 | S5: 150 | X5: 6.3 | AD5: ④ | AE5: N치를 기반으로 아래 개략산출식으로 점착력 및 내부마찰각을 산출하여 보수적으로 기입한다. (N11~N15, R11~R15) | BC5: (tf/m2) | BE5: Es | BG5: Es'
AD6: ⑤ | AE6: 주상도를 보고 옆의 표에서 깊이별 N치를 기입(BN행)한다. | AX6: 0 | AY6: ~ | AZ6: 1 | BA6: =AZ6-AX6 -> 1 | BC6: =1200*(BN6+6) -> 18000 | BD6: =IF(BA6="","",(IF(BJ6<0.5*$G$5,((BJ6/$G$5+0.125)/1.25),((BJ6/$G$5)-2)/(-3)))) -> 0.14761905 | BE6: =IF(BD6<0,0,+BD6*BA6/BC6) -> 8.2010582e-06 | BG6: 매립층 | BJ6: =SUM(BA6)/2 -> 0.5 | BL6: 1 | BN6: 9 | BQ6: ▶ | BR6: 현장 시험 결과와 탄성 계수 (Es, qc는 Kpa 단위임. 1Kpa=0.1tf/㎡)
AD7: ⑥ | AE7: 입력한 N치를 대입하여 적정 공식을 이용하여 변형계수를 산출한다. (BC행) | AX7: =+AZ6 -> 1 | AY7: ~ | AZ7: 2 | BA7: =AZ7-AX7 -> 1 | BC7: =1200*(BN7+6) -> 20400 | BD7: =IF(BA7="","",(IF(BJ7<0.5*$G$5,((BJ7/$G$5+0.125)/1.25),((BJ7/$G$5)-2)/(-3)))) -> 0.24285714 | BE7: =IF(BD7<0,0,+BD7*BA7/BC7) -> 1.1904762e-05 | BG7: 매립층 | BJ7: =SUM(BA6)+(BA7/2) -> 1.5 | BL7: 2 | BN7: 11 | BQ7: 흙의 종류 | BV7: S.P.T | CA7: C.P.T
B8: 2.원지반 대표상수 | AD8: ⑦ | AE8: 2. 원지반 대표상수의 변형계수 값을 기입한다.(U11~U15) | AX8: =+AZ7 -> 2 | AY8: ~ | AZ8: 3 | BA8: =AZ8-AX8 -> 1 | BC8: =1200*(BN8+6) -> 32400 | BD8: =IF(BA8="","",(IF(BJ8<0.5*$G$5,((BJ8/$G$5+0.125)/1.25),((BJ8/$G$5)-2)/(-3)))) -> 0.33809524 | BE8: =IF(BD8<0,0,+BD8*BA8/BC8) -> 1.0435038e-05 | BG8: 매립층 | BJ8: =SUM(BA$6:BA7)+(BA8/2) -> 2.5 | BL8: 3 | BN8: 21 | BQ8: 모 래 | BV8: Es = 766N
B9: 토층 | D9: 두께 | H9: 평균두께 | K9: 단위중량 | N9: 점착력 | P9: 점착력 가중 평균 | R9: 내부마찰각 | U9: 변형계수 | X9: 비고 | AH9: radian | AK9: 마찰각 가중 | AX9: =+AZ8 -> 3 | AY9: ~ | AZ9: 4 | BA9: =AZ9-AX9 -> 1 | BC9: =1200*(BN9+6) -> 21600 | BD9: =IF(BA9="","",(IF(BJ9<0.5*$G$5,((BJ9/$G$5+0.125)/1.25),((BJ9/$G$5)-2)/(-3)))) -> 0.43333333 | BE9: =IF(BD9<0,0,+BD9*BA9/BC9) -> 2.0061728e-05 | BG9: 매립층 | BJ9: =SUM(BA$6:BA8)+(BA9/2) -> 3.5 | BL9: 4 | BN9: 12 | BV9: Es = 500( N + 15 ) | CA9: Es = ( 2 ~ 4)qc
H10: m | K10: KN/㎡ | N10: KN/㎡ | R10: ° | U10: KN/㎡ | AX10: =+AZ9 -> 4 | AY10: ~ | AZ10: 5 | BA10: =AZ10-AX10 -> 1 | BC10: =1200*(BN10+6) -> 25200 | BD10: =IF(BA10="","",(IF(BJ10<0.5*$G$5,((BJ10/$G$5+0.125)/1.25),((BJ10/$G$5)-2)/(-3)))) -> 0.48809524 | BE10: =IF(BD10<0,0,+BD10*BA10/BC10) -> 1.9368859e-05 | BG10: 매립층 | BJ10: =SUM(BA$6:BA9)+(BA10/2) -> 4.5 | BL10: 5 | BN10: 15 | BV10: Es = 18,000 + 750N | CA10: Es = 2( 1 + Dr2 )qc
B11: 매립층 | D11: 0 | F11: 0 | H11: =F11-D11 -> 0 | K11: 18 | N11: 3 | P11: =+N11*H11 -> 0 | R11: 23 | U11: =+BC6 -> 18000 | X11: 실트질모래 | AH11: =+ROUND(RADIANS(R11),4) -> 0.4014 | AK11: =+ROUND(TAN(AH11)*H11,4) -> 0 | AX11: =+AZ10 -> 5 | AY11: ~ | AZ11: 6 | BA11: =AZ11-AX11 -> 1 | BC11: =1200*(BN11+6) -> 15600 | BD11: =IF(BA11="","",(IF(BJ11<0.5*$G$5,((BJ11/$G$5+0.125)/1.25),((BJ11/$G$5)-2)/(-3)))) -> 0.4484127 | BE11: =IF(BD11<0,0,+BD11*BA11/BC11) -> 2.8744404e-05 | BG11: 매립층 | BJ11: =SUM(BA$6:BA10)+(BA11/2) -> 5.5 | BL11: 6 | BN11: 7 | BV11: Es = (15,200 ~ 22,000)lnN
B12: 퇴적층 | D12: 7.4 | F12: 8 | H12: =F12-D12 -> 0.6 | K12: 18 | N12: 3 | P12: =+N12*H12 -> 1.8 | R12: 23 | U12: =+BC13 -> 30000 | X12: 실트질모래 | AH12: =+ROUND(RADIANS(R12),4) -> 0.4014 | AK12: =+ROUND(TAN(AH12)*H12,5) -> 0.25467 | AX12: =AZ11 -> 6 | AY12: ~ | AZ12: 7 | BA12: =AZ12-AX12 -> 1 | BC12: =1200*(BN12+6) -> 21600 | BD12: =IF(BA12="","",(IF(BJ12<0.5*$G$5,((BJ12/$G$5+0.125)/1.25),((BJ12/$G$5)-2)/(-3)))) -> 0.40873016 | BE12: =IF(BD12<0,0,+BD12*BA12/BC12) -> 1.8922693e-05 | BG12: 퇴적층 | BJ12: =SUM(BA$6:BA11)+(BA12/2) -> 6.5 | BL12: 7 | BN12: 12 | BQ12: 점토질 모래 | BV12: Es = 320( N + 15 ) | CA12: Es = ( 3 ~ 6 )6qc
B13: 풍화토 | D13: =+F12 -> 8 | F13: 20 | H13: =F13-D13 -> 12 | K13: 19 | N13: 5 | P13: =+N13*H13 -> 60 | R13: 25 | U13: =+BC16 -> 27000 | X13: 실트질모래 | AH13: =+ROUND(RADIANS(R13),4) -> 0.4363 | AK13: =+ROUND(TAN(AH13)*H13,5) -> 5.59522 | AX13: =AZ12 -> 7 | AY13: ~ | AZ13: 8 | BA13: =AZ13-AX13 -> 1 | BC13: =1200*(BN13+6) -> 30000 | BD13: =IF(BA13="","",(IF(BJ13<0.5*$G$5,((BJ13/$G$5+0.125)/1.25),((BJ13/$G$5)-2)/(-3)))) -> 0.36904762 | BE13: =IF(BD13<0,0,+BD13*BA13/BC13) -> 1.2301587e-05 | BG13: 퇴적층 | BJ13: =SUM(BA$6:BA12)+(BA13/2) -> 7.5 | BL13: 8 | BN13: 19 | BQ13: 실트질 모래 | BV13: Es = 300( N + 6 ) | CA13: Es = 1에서 Pc
B14: 풍화암 | D14: =F13 -> 20 | F14: 22 | H14: =F14-D14 -> 2 | K14: 20 | N14: 10 | P14: =+N14*H14 -> 20 | R14: 27 | U14: =+BC26 -> 264000 | AH14: =+ROUND(RADIANS(R14),4) -> 0.4712 | AK14: =+ROUND(TAN(AH14)*H14,5) -> 1.01895 | AX14: =AZ13 -> 8 | AY14: ~ | AZ14: 9 | BA14: =AZ14-AX14 -> 1 | BC14: =300*(BN14+6) -> 9900 | BD14: =IF(BA14="","",(IF(BJ14<0.5*$G$5,((BJ14/$G$5+0.125)/1.25),((BJ14/$G$5)-2)/(-3)))) -> 0.32936508 | BE14: =IF(BD14<0,0,+BD14*BA14/BC14) -> 3.32692e-05 | BG14: 풍화토 | BJ14: =SUM(BA$6:BA13)+(BA14/2) -> 8.5 | BL14: 9 | BN14: 27 | BQ14: 자갈섞인 모래 | BV14: Es = 1,200( N + 6 )
H15: =F15-D15 -> 0 | AH15: =+ROUND(RADIANS(R15),4) -> 0 | AK15: =+ROUND(TAN(AH15)*H15,5) -> 0 | AX15: =AZ14 -> 9 | AY15: ~ | AZ15: 10 | BA15: =AZ15-AX15 -> 1 | BC15: =500*(BN15+15) -> 25000 | BD15: =IF(BA15="","",(IF(BJ15<0.5*$G$5,((BJ15/$G$5+0.125)/1.25),((BJ15/$G$5)-2)/(-3)))) -> 0.28968254 | BE15: =IF(BD15<0,0,+BD15*BA15/BC15) -> 1.1587302e-05 | BG15: 풍화토 | BJ15: =SUM(BA$6:BA14)+(BA15/2) -> 9.5 | BL15: 10 | BN15: 35 | BQ15: 연약 점토 | CA15: Es = ( 6 ~ 8 )qc
B16: 합계 | H16: =SUM(H11:J15) -> 14.6 | P16: =SUM(P11:Q15) -> 81.8 | AD16: 한계깊이를 구한후 | AK16: =SUM(AK11:AK15) -> 6.86884 | AX16: =AZ15 -> 10 | AY16: ~ | AZ16: 11 | BA16: =AZ16-AX16 -> 1 | BC16: =500*(BN16+15) -> 27000 | BD16: =IF(BA16="","",(IF(BJ16<0.5*$G$5,((BJ16/$G$5+0.125)/1.25),((BJ16/$G$5)-2)/(-3)))) -> 0.25 | BE16: =IF(BD16<0,0,+BD16*BA16/BC16) -> 9.2592593e-06 | BG16: 풍화토 | BJ16: =SUM(BA$6:BA15)+(BA16/2) -> 10.5 | BL16: 11 | BN16: 39 | BQ16: 점 토 | BV16: Ip > 30, 또는 유기질 | CA16: Es = ( 100 ~ 500 )Su
AD17: 합계깊이를 수정함 | AH17: 마찰각(rad) | AK17: =+AK16/H16 -> 0.47046849 | AX17: =AZ16 -> 11 | AY17: ~ | AZ17: 12 | BA17: =AZ17-AX17 -> 1 | BC17: =500*(BN17+15) -> 30500 | BD17: =IF(BA17="","",(IF(BJ17<0.5*$G$5,((BJ17/$G$5+0.125)/1.25),((BJ17/$G$5)-2)/(-3)))) -> 0.21031746 | BE17: =IF(BD17<0,0,+BD17*BA17/BC17) -> 6.8956544e-06 | BG17: 풍화토 | BJ17: =SUM(BA$6:BA16)+(BA17/2) -> 11.5 | BL17: 12 | BN17: 46 | BV17: Ip = ( 2 ~ 4 )qc | CA17: Es = ( 500 ~ 1,500 )Su
AH18: 가중평균마찰각(rad) | AK18: =+ATAN(AK17) -> 0.43974455 | AX18: =AZ17 -> 12 | AY18: ~ | AZ18: 13 | BA18: =AZ18-AX18 -> 1 | BC18: =500*(BN18+15) -> 31000 | BD18: =IF(BA18="","",(IF(BJ18<0.5*$G$5,((BJ18/$G$5+0.125)/1.25),((BJ18/$G$5)-2)/(-3)))) -> 0.17063492 | BE18: =IF(BD18<0,0,+BD18*BA18/BC18) -> 5.5043523e-06 | BG18: 풍화토 | BJ18: =SUM(BA$6:BA17)+(BA18/2) -> 12.5 | BL18: 13 | BN18: 47 | BQ18: (Su:비배수전단강도) | BV18: 1 < O.C.R < 2 | CA18: Es = (800 ~ 1,200)Su
B19: 점착력 가중평균 | I19: = | K19: =P16&" / ("&H16&")" -> 81.8 / (14.6) | X19: = | Y19: =+ROUND(P16/(H16),2) -> 5.6 | AH19: 가중평균마찰각(degree) | AK19: =+DEGREES(AK18) -> 25.195507 | AX19: =AZ18 -> 13 | AY19: ~ | AZ19: 14 | BA19: =AZ19-AX19 -> 1 | BC19: =500*(BN19+15) -> 33000 | BD19: =IF(BA19="","",(IF(BJ19<0.5*$G$5,((BJ19/$G$5+0.125)/1.25),((BJ19/$G$5)-2)/(-3)))) -> 0.13095238 | BE19: =IF(BD19<0,0,+BD19*BA19/BC19) -> 3.968254e-06 | BG19: 풍화토 | BJ19: =SUM(BA$6:BA18)+(BA19/2) -> 13.5 | BL19: 14 | BN19: 51 | BV19: O.C.R > 2 | CA19: Es = (1,500 ~ 2,000)Su
AX20: =AZ19 -> 14 | AY20: ~ | AZ20: 15 | BA20: =AZ20-AX20 -> 1 | BC20: =500*(BN20+15) -> 36000 | BD20: =IF(BA20="","",(IF(BJ20<0.5*$G$5,((BJ20/$G$5+0.125)/1.25),((BJ20/$G$5)-2)/(-3)))) -> 0.091269841 | BE20: =IF(BD20<0,0,+BD20*BA20/BC20) -> 2.5352734e-06 | BG20: 풍화토 | BJ20: =SUM(BA$6:BA19)+(BA20/2) -> 14.5 | BL20: 15 | BN20: 57
B21: 내부마찰각 가중평균 | K21: ="DEGREE(" & BD20 & ") " -> DEGREE(0.0912698412698413) | X21: = | Y21: =ROUND(DEGREES(AK18),2) -> 25.2 | AB21: (DEGREE) | AX21: =AZ20 -> 15 | AY21: ~ | AZ21: 16 | BA21: =AZ21-AX21 -> 1 | BC21: =500*(BN21+15) -> 49000 | BD21: =IF(BA21="","",(IF(BJ21<0.5*$G$5,((BJ21/$G$5+0.125)/1.25),((BJ21/$G$5)-2)/(-3)))) -> 0.051587302 | BE21: =IF(BD21<0,0,+BD21*BA21/BC21) -> 1.0528021e-06 | BG21: 풍화토 | BJ21: =SUM(BA$6:BA20)+(BA21/2) -> 15.5 | BL21: 16 | BN21: 83
AX22: =AZ21 -> 16 | AY22: ~ | AZ22: 17 | BA22: =AZ22-AX22 -> 1 | BC22: =500*(BN22+15) -> 54000 | BD22: =IF(BA22="","",(IF(BJ22<0.5*$G$5,((BJ22/$G$5+0.125)/1.25),((BJ22/$G$5)-2)/(-3)))) -> 0.011904762 | BE22: =IF(BD22<0,0,+BD22*BA22/BC22) -> 2.2045855e-07 | BG22: 풍화토 | BJ22: =SUM(BA$6:BA21)+(BA22/2) -> 16.5 | BL22: 17 | BN22: 93
AX23: =AZ22 -> 17 | AY23: ~ | AZ23: 18 | BA23: =AZ23-AX23 -> 1 | BC23: =500*(BN23+15) -> 70000 | BD23: =IF(BA23="","",(IF(BJ23<0.5*$G$5,((BJ23/$G$5+0.125)/1.25),((BJ23/$G$5)-2)/(-3)))) -> -0.027777778 | BE23: =IF(BD23<0,0,+BD23*BA23/BC23) -> 0 | BG23: 풍화토 | BJ23: =SUM(BA$6:BA22)+(BA23/2) -> 17.5 | BL23: 18 | BN23: 125
AX24: =AZ23 -> 18 | AY24: ~ | AZ24: 19 | BA24: =AZ24-AX24 -> 1 | BC24: =500*(BN24+15) -> 70000 | BD24: =IF(BA24="","",(IF(BJ24<0.5*$G$5,((BJ24/$G$5+0.125)/1.25),((BJ24/$G$5)-2)/(-3)))) -> -0.067460317 | BE24: =IF(BD24<0,0,+BD24*BA24/BC24) -> 0 | BG24: 풍화토 | BJ24: =SUM(BA$6:BA23)+(BA24/2) -> 18.5 | BL24: 19 | BN24: 125
AX25: =AZ24 -> 19 | AY25: ~ | AZ25: 20 | BA25: =AZ25-AX25 -> 1 | BC25: =500*(BN25+15) -> 114500 | BD25: =IF(BA25="","",(IF(BJ25<0.5*$G$5,((BJ25/$G$5+0.125)/1.25),((BJ25/$G$5)-2)/(-3)))) -> -0.10714286 | BE25: =IF(BD25<0,0,+BD25*BA25/BC25) -> 0 | BG25: 풍화토 | BJ25: =SUM($BA$6:BA24)+(BA25/2) -> 19.5 | BL25: 20 | BN25: 214
AX26: =AZ25 -> 20 | AY26: ~ | AZ26: 21 | BA26: =AZ26-AX26 -> 1 | BC26: =1200*(BN26+6) -> 264000 | BD26: =IF(BA26="","",(IF(BJ26<0.5*$G$5,((BJ26/$G$5+0.125)/1.25),((BJ26/$G$5)-2)/(-3)))) -> -0.1468254 | BE26: =IF(BD26<0,0,+BD26*BA26/BC26) -> 0 | BG26: 풍화암 | BJ26: =SUM($BA$6:BA25)+(BA26/2) -> 20.5 | BL26: 21 | BN26: 214
AX27: =AZ26 -> 21 | AY27: ~ | AZ27: 22 | BA27: =AZ27-AX27 -> 1 | BC27: =1200*(BN27+6) -> 264000 | BD27: =IF(BA27="","",(IF(BJ27<0.5*$G$5,((BJ27/$G$5+0.125)/1.25),((BJ27/$G$5)-2)/(-3)))) -> -0.18650794 | BE27: =IF(BD27<0,0,+BD27*BA27/BC27) -> 0 | BG27: 풍화암 | BJ27: =SUM($BA$6:BA26)+(BA27/2) -> 21.5 | BL27: 22 | BN27: 214
AX28: 0 | AY28: ~ | BA28: =AZ28-AX28 -> 0 | BC28: =1200*(BN28+6) -> 7200 | BD28: =IF(BA28="","",(IF(BJ28<0.5*$G$5,((BJ28/$G$5+0.125)/1.25),((BJ28/$G$5)-2)/(-3)))) -> -0.20634921 | BE28: =IF(BD28<0,0,+BD28*BA28/BC28) -> 0 | BJ28: =SUM($BA$6:BA27)+(BA28/2) -> 22 | BL28: 23
AX29: =AZ28 -> 0 | AY29: ~ | BA29: =AZ29-AX29 -> 0 | BC29: =1200*(BN29+6) -> 7200 | BD29: =IF(BA29="","",(IF(BJ29<0.5*$G$5,((BJ29/$G$5+0.125)/1.25),((BJ29/$G$5)-2)/(-3)))) -> -0.20634921 | BE29: =IF(BD29<0,0,+BD29*BA29/BC29) -> 0 | BJ29: =SUM($BA$6:BA28)+(BA29/2) -> 22 | BL29: 24
AX30: =AZ29 -> 0 | AY30: ~ | BA30: =AZ30-AX30 -> 0 | BC30: =1200*(BN30+6) -> 7200 | BD30: =IF(BA30="","",(IF(BJ30<0.5*$G$5,((BJ30/$G$5+0.125)/1.25),((BJ30/$G$5)-2)/(-3)))) -> -0.20634921 | BE30: =IF(BD30<0,0,+BD30*BA30/BC30) -> 0 | BJ30: =SUM($BA$6:BA29)+(BA30/2) -> 22 | BL30: 25
AX31: =AZ30 -> 0 | AY31: ~ | BA31: =AZ31-AX31 -> 0 | BC31: =1200*(BN31+6) -> 7200 | BD31: =IF(BA31="","",(IF(BJ31<0.5*$G$5,((BJ31/$G$5+0.125)/1.25),((BJ31/$G$5)-2)/(-3)))) -> -0.20634921 | BE31: =IF(BD31<0,0,+BD31*BA31/BC31) -> 0 | BJ31: =SUM($BA$6:BA30)+(BA31/2) -> 22 | BL31: 26
AX32: =+AZ31 -> 0 | AY32: ~ | BA32: =AZ32-AX32 -> 0 | BC32: =1200*(BN32+6) -> 7200 | BD32: =IF(BA32="","",(IF(BJ32<0.5*$G$5,((BJ32/$G$5+0.125)/1.25),((BJ32/$G$5)-2)/(-3)))) -> -0.20634921 | BE32: =IF(BD32<0,0,+BD32*BA32/BC32) -> 0 | BJ32: =SUM($BA$6:BA31)+(BA32/2) -> 22 | BL32: 27
BE33: ∑
B37: 지반조사결과 매립층-퇴적층-풍화토-풍화암층의 순서로 지반이 구성
B38: 기초근입깊이가 7.4m로 퇴적층 위에 기초가 자리잡으며 20.0m 깊이에 기반암인 풍화암이 위치함
B39: 지지력 및 침하량 계산시 한계깊이(Hf)를 산출하거나 풍화암 2.0m까지인 22m까지 계산함
B43: 3. 강도전수 산정
B45: 1) | C45: 지반의 점착력
B46: * | C46: 기초 하부의 N 값 | H46: : | I46: 12 | K46: ( N < 30 )
C47: C=qu/2 | F47: Ø=0
...

Sheet B-5.1(무보강)
A1: ▶ | B1: 페블테크 지내력 검토(KDN충북사업처) - 지하층
B2: 1.구조물 기초 일반조건 | AD2: ① | AE2: 도면을 참조하여 시추공번호, 기초폭, 길이, 근입깊이, 설계하중, 지하수위를 기입한다 (B5~X5)
B3: 검토단면 | G3: 기초형상 | O3: 근입깊이 | S3: 하중조건 | X3: 지하수위 | AD3: ② | AE3: 지반조사서의 지반 층의 구별대로 토층 및 깊이를 기입한다. (D11~F15) | BM3: N치-주상도 입력
G4: B(m) | K4: L(m) | O4: m | S4: KN/㎡ | X4: m | AD4: ③ | AE4: N치를 고려하여 토층의 단위중량을 기입한다 (K11~K15) | AX4: 길 이 (m) | BA4: △Z (m) | BC4: E s | BD4: 평균 I z | BE4: I z | BF4: ㆍ△Z | BG4: I z | BH4: ㆍ△Z | BJ4: Zp (m) | BL4: 심도 | BN4: N치
B5: BH-2 | G5: 8.4 | K5: 8.8 | O5: 5.1 | S5: 150 | X5: 6.3 | AD5: ④ | AE5: N치를 기반으로 아래 개략산출식으로 점착력 및 내부마찰각을 산출하여 보수적으로 기입한다. (N11~N15, R11~R15) | BC5: (tf/m2) | BE5: Es | BG5: Es'
AD6: ⑤ | AE6: 주상도를 보고 옆의 표에서 깊이별 N치를 기입(BN행)한다. | AX6: 0 | AY6: ~ | AZ6: 1 | BA6: =AZ6-AX6 -> 1 | BC6: =1200*(BN6+6) -> 18000 | BD6: =IF(BA6="","",(IF(BJ6<0.5*$G$5,((BJ6/$G$5+0.125)/1.25),((BJ6/$G$5)-2)/(-3)))) -> 0.14761905 | BE6: =IF(BD6<0,0,+BD6*BA6/BC6) -> 8.2010582e-06 | BG6: 매립층 | BJ6: =SUM(BA6)/2 -> 0.5 | BL6: 1 | BN6: 9 | BQ6: ▶ | BR6: 현장 시험 결과와 탄성 계수 (Es, qc는 Kpa 단위임. 1Kpa=0.1tf/㎡)
AD7: ⑥ | AE7: 입력한 N치를 대입하여 적정 공식을 이용하여 변형계수를 산출한다. (BC행) | AX7: =+AZ6 -> 1 | AY7: ~ | AZ7: 2 | BA7: =AZ7-AX7 -> 1 | BC7: =1200*(BN7+6) -> 20400 | BD7: =IF(BA7="","",(IF(BJ7<0.5*$G$5,((BJ7/$G$5+0.125)/1.25),((BJ7/$G$5)-2)/(-3)))) -> 0.24285714 | BE7: =IF(BD7<0,0,+BD7*BA7/BC7) -> 1.1904762e-05 | BG7: 매립층 | BJ7: =SUM(BA6)+(BA7/2) -> 1.5 | BL7: 2 | BN7: 11 | BQ7: 흙의 종류 | BV7: S.P.T | CA7: C.P.T
B8: 2.원지반 대표상수 | AD8: ⑦ | AE8: 2. 원지반 대표상수의 변형계수 값을 기입한다.(U11~U15) | AX8: =+AZ7 -> 2 | AY8: ~ | AZ8: 3 | BA8: =AZ8-AX8 -> 1 | BC8: =1200*(BN8+6) -> 32400 | BD8: =IF(BA8="","",(IF(BJ8<0.5*$G$5,((BJ8/$G$5+0.125)/1.25),((BJ8/$G$5)-2)/(-3)))) -> 0.33809524 | BE8: =IF(BD8<0,0,+BD8*BA8/BC8) -> 1.0435038e-05 | BG8: 매립층 | BJ8: =SUM(BA$6:BA7)+(BA8/2) -> 2.5 | BL8: 3 | BN8: 21 | BQ8: 모 래 | BV8: Es = 766N
B9: 토층 | D9: 두께 | H9: 평균두께 | K9: 단위중량 | N9: 점착력 | P9: 점착력 가중 평균 | R9: 내부마찰각 | U9: 변형계수 | X9: 비고 | AH9: radian | AK9: 마찰각 가중 | AX9: =+AZ8 -> 3 | AY9: ~ | AZ9: 4 | BA9: =AZ9-AX9 -> 1 | BC9: =1200*(BN9+6) -> 21600 | BD9: =IF(BA9="","",(IF(BJ9<0.5*$G$5,((BJ9/$G$5+0.125)/1.25),((BJ9/$G$5)-2)/(-3)))) -> 0.43333333 | BE9: =IF(BD9<0,0,+BD9*BA9/BC9) -> 2.0061728e-05 | BG9: 매립층 | BJ9: =SUM(BA$6:BA8)+(BA9/2) -> 3.5 | BL9: 4 | BN9: 12 | BV9: Es = 500( N + 15 ) | CA9: Es = ( 2 ~ 4)qc
H10: m | K10: KN/㎡ | N10: KN/㎡ | R10: ° | U10: KN/㎡ | AX10: =+AZ9 -> 4 | AY10: ~ | AZ10: 5 | BA10: =AZ10-AX10 -> 1 | BC10: =1200*(BN10+6) -> 25200 | BD10: =IF(BA10="","",(IF(BJ10<0.5*$G$5,((BJ10/$G$5+0.125)/1.25),((BJ10/$G$5)-2)/(-3)))) -> 0.48809524 | BE10: =IF(BD10<0,0,+BD10*BA10/BC10) -> 1.9368859e-05 | BG10: 매립층 | BJ10: =SUM(BA$6:BA9)+(BA10/2) -> 4.5 | BL10: 5 | BN10: 15 | BV10: Es = 18,000 + 750N | CA10: Es = 2( 1 + Dr2 )qc
B11: 매립층 | D11: 5.1 | F11: 5.6 | H11: =F11-D11 -> 0.5 | K11: 18 | N11: 3 | P11: =+N11*H11 -> 1.5 | R11: 23 | U11: =+BC6 -> 18000 | X11: 실트질모래 | AH11: =+ROUND(RADIANS(R11),4) -> 0.4014 | AK11: =+ROUND(TAN(AH11)*H11,4) -> 0.2122 | AX11: =+AZ10 -> 5 | AY11: ~ | AZ11: 6 | BA11: =AZ11-AX11 -> 1 | BC11: =1200*(BN11+6) -> 15600 | BD11: =IF(BA11="","",(IF(BJ11<0.5*$G$5,((BJ11/$G$5+0.125)/1.25),((BJ11/$G$5)-2)/(-3)))) -> 0.4484127 | BE11: =IF(BD11<0,0,+BD11*BA11/BC11) -> 2.8744404e-05 | BG11: 매립층 | BJ11: =SUM(BA$6:BA10)+(BA11/2) -> 5.5 | BL11: 6 | BN11: 7 | BV11: Es = (15,200 ~ 22,000)lnN
B12: 퇴적층 | D12: =+F11 -> 5.6 | F12: 8 | H12: =F12-D12 -> 2.4 | K12: 18 | N12: 3 | P12: =+N12*H12 -> 7.2 | R12: 23 | U12: =+BC13 -> 30000 | X12: 실트질모래 | AH12: =+ROUND(RADIANS(R12),4) -> 0.4014 | AK12: =+ROUND(TAN(AH12)*H12,5) -> 1.01867 | AX12: =AZ11 -> 6 | AY12: ~ | AZ12: 7 | BA12: =AZ12-AX12 -> 1 | BC12: =1200*(BN12+6) -> 21600 | BD12: =IF(BA12="","",(IF(BJ12<0.5*$G$5,((BJ12/$G$5+0.125)/1.25),((BJ12/$G$5)-2)/(-3)))) -> 0.40873016 | BE12: =IF(BD12<0,0,+BD12*BA12/BC12) -> 1.8922693e-05 | BG12: 퇴적층 | BJ12: =SUM(BA$6:BA11)+(BA12/2) -> 6.5 | BL12: 7 | BN12: 12 | BQ12: 점토질 모래 | BV12: Es = 320( N + 15 ) | CA12: Es = ( 3 ~ 6 )6qc
B13: 풍화토 | D13: =+F12 -> 8 | F13: 20 | H13: =F13-D13 -> 12 | K13: 19 | N13: 5 | P13: =+N13*H13 -> 60 | R13: 25 | U13: =+BC16 -> 27000 | X13: 실트질모래 | AH13: =+ROUND(RADIANS(R13),4) -> 0.4363 | AK13: =+ROUND(TAN(AH13)*H13,5) -> 5.59522 | AX13: =AZ12 -> 7 | AY13: ~ | AZ13: 8 | BA13: =AZ13-AX13 -> 1 | BC13: =1200*(BN13+6) -> 30000 | BD13: =IF(BA13="","",(IF(BJ13<0.5*$G$5,((BJ13/$G$5+0.125)/1.25),((BJ13/$G$5)-2)/(-3)))) -> 0.36904762 | BE13: =IF(BD13<0,0,+BD13*BA13/BC13) -> 1.2301587e-05 | BG13: 퇴적층 | BJ13: =SUM(BA$6:BA12)+(BA13/2) -> 7.5 | BL13: 8 | BN13: 19 | BQ13: 실트질 모래 | BV13: Es = 300( N + 6 ) | CA13: Es = 1에서 Pc
B14: 풍화암 | D14: =F13 -> 20 | F14: 22 | H14: =F14-D14 -> 2 | K14: 20 | N14: 10 | P14: =+N14*H14 -> 20 | R14: 27 | U14: =+BC26 -> 264000 | AH14: =+ROUND(RADIANS(R14),4) -> 0.4712 | AK14: =+ROUND(TAN(AH14)*H14,5) -> 1.01895 | AX14: =AZ13 -> 8 | AY14: ~ | AZ14: 9 | BA14: =AZ14-AX14 -> 1 | BC14: =300*(BN14+6) -> 9900 | BD14: =IF(BA14="","",(IF(BJ14<0.5*$G$5,((BJ14/$G$5+0.125)/1.25),((BJ14/$G$5)-2)/(-3)))) -> 0.32936508 | BE14: =IF(BD14<0,0,+BD14*BA14/BC14) -> 3.32692e-05 | BG14: 풍화토 | BJ14: =SUM(BA$6:BA13)+(BA14/2) -> 8.5 | BL14: 9 | BN14: 27 | BQ14: 자갈섞인 모래 | BV14: Es = 1,200( N + 6 )
H15: =F15-D15 -> 0 | AH15: =+ROUND(RADIANS(R15),4) -> 0 | AK15: =+ROUND(TAN(AH15)*H15,5) -> 0 | AX15: =AZ14 -> 9 | AY15: ~ | AZ15: 10 | BA15: =AZ15-AX15 -> 1 | BC15: =500*(BN15+15) -> 25000 | BD15: =IF(BA15="","",(IF(BJ15<0.5*$G$5,((BJ15/$G$5+0.125)/1.25),((BJ15/$G$5)-2)/(-3)))) -> 0.28968254 | BE15: =IF(BD15<0,0,+BD15*BA15/BC15) -> 1.1587302e-05 | BG15: 풍화토 | BJ15: =SUM(BA$6:BA14)+(BA15/2) -> 9.5 | BL15: 10 | BN15: 35 | BQ15: 연약 점토 | CA15: Es = ( 6 ~ 8 )qc
B16: 합계 | H16: =SUM(H11:J15) -> 16.9 | P16: =SUM(P11:Q15) -> 88.7 | AD16: 한계깊이를 구한후 | AK16: =SUM(AK11:AK15) -> 7.84504 | AX16: =AZ15 -> 10 | AY16: ~ | AZ16: 11 | BA16: =AZ16-AX16 -> 1 | BC16: =500*(BN16+15) -> 27000 | BD16: =IF(BA16="","",(IF(BJ16<0.5*$G$5,((BJ16/$G$5+0.125)/1.25),((BJ16/$G$5)-2)/(-3)))) -> 0.25 | BE16: =IF(BD16<0,0,+BD16*BA16/BC16) -> 9.2592593e-06 | BG16: 풍화토 | BJ16: =SUM(BA$6:BA15)+(BA16/2) -> 10.5 | BL16: 11 | BN16: 39 | BQ16: 점 토 | BV16: Ip > 30, 또는 유기질 | CA16: Es = ( 100 ~ 500 )Su
AD17: 합계깊이를 수정함 | AH17: 마찰각(rad) | AK17: =+AK16/H16 -> 0.46420355 | AX17: =AZ16 -> 11 | AY17: ~ | AZ17: 12 | BA17: =AZ17-AX17 -> 1 | BC17: =500*(BN17+15) -> 30500 | BD17: =IF(BA17="","",(IF(BJ17<0.5*$G$5,((BJ17/$G$5+0.125)/1.25),((BJ17/$G$5)-2)/(-3)))) -> 0.21031746 | BE17: =IF(BD17<0,0,+BD17*BA17/BC17) -> 6.8956544e-06 | BG17: 풍화토 | BJ17: =SUM(BA$6:BA16)+(BA17/2) -> 11.5 | BL17: 12 | BN17: 46 | BV17: Ip = ( 2 ~ 4 )qc | CA17: Es = ( 500 ~ 1,500 )Su
AH18: 가중평균마찰각(rad) | AK18: =+ATAN(AK17) -> 0.43460262 | AX18: =AZ17 -> 12 | AY18: ~ | AZ18: 13 | BA18: =AZ18-AX18 -> 1 | BC18: =500*(BN18+15) -> 31000 | BD18: =IF(BA18="","",(IF(BJ18<0.5*$G$5,((BJ18/$G$5+0.125)/1.25),((BJ18/$G$5)-2)/(-3)))) -> 0.17063492 | BE18: =IF(BD18<0,0,+BD18*BA18/BC18) -> 5.5043523e-06 | BG18: 풍화토 | BJ18: =SUM(BA$6:BA17)+(BA18/2) -> 12.5 | BL18: 13 | BN18: 47 | BQ18: (Su:비배수전단강도) | BV18: 1 < O.C.R < 2 | CA18: Es = (800 ~ 1,200)Su
B19: 점착력 가중평균 | I19: = | K19: =P16&" / ("&H16&")" -> 88.7 / (16.9) | X19: = | Y19: =+ROUND(P16/(H16),2) -> 5.25 | AH19: 가중평균마찰각(degree) | AK19: =+DEGREES(AK18) -> 24.900896 | AX19: =AZ18 -> 13 | AY19: ~ | AZ19: 14 | BA19: =AZ19-AX19 -> 1 | BC19: =500*(BN19+15) -> 33000 | BD19: =IF(BA19="","",(IF(BJ19<0.5*$G$5,((BJ19/$G$5+0.125)/1.25),((BJ19/$G$5)-2)/(-3)))) -> 0.13095238 | BE19: =IF(BD19<0,0,+BD19*BA19/BC19) -> 3.968254e-06 | BG19: 풍화토 | BJ19: =SUM(BA$6:BA18)+(BA19/2) -> 13.5 | BL19: 14 | BN19: 51 | BV19: O.C.R > 2 | CA19: Es = (1,500 ~ 2,000)Su
AX20: =AZ19 -> 14 | AY20: ~ | AZ20: 15 | BA20: =AZ20-AX20 -> 1 | BC20: =500*(BN20+15) -> 36000 | BD20: =IF(BA20="","",(IF(BJ20<0.5*$G$5,((BJ20/$G$5+0.125)/1.25),((BJ20/$G$5)-2)/(-3)))) -> 0.091269841 | BE20: =IF(BD20<0,0,+BD20*BA20/BC20) -> 2.5352734e-06 | BG20: 풍화토 | BJ20: =SUM(BA$6:BA19)+(BA20/2) -> 14.5 | BL20: 15 | BN20: 57
B21: 내부마찰각 가중평균 | K21: ="DEGREE(" & BD20 & ") " -> DEGREE(0.0912698412698413) | X21: = | Y21: =ROUND(DEGREES(AK18),2) -> 24.9 | AB21: (DEGREE) | AX21: =AZ20 -> 15 | AY21: ~ | AZ21: 16 | BA21: =AZ21-AX21 -> 1 | BC21: =500*(BN21+15) -> 49000 | BD21: =IF(BA21="","",(IF(BJ21<0.5*$G$5,((BJ21/$G$5+0.125)/1.25),((BJ21/$G$5)-2)/(-3)))) -> 0.051587302 | BE21: =IF(BD21<0,0,+BD21*BA21/BC21) -> 1.0528021e-06 | BG21: 풍화토 | BJ21: =SUM(BA$6:BA20)+(BA21/2) -> 15.5 | BL21: 16 | BN21: 83
AX22: =AZ21 -> 16 | AY22: ~ | AZ22: 17 | BA22: =AZ22-AX22 -> 1 | BC22: =500*(BN22+15) -> 54000 | BD22: =IF(BA22="","",(IF(BJ22<0.5*$G$5,((BJ22/$G$5+0.125)/1.25),((BJ22/$G$5)-2)/(-3)))) -> 0.011904762 | BE22: =IF(BD22<0,0,+BD22*BA22/BC22) -> 2.2045855e-07 | BG22: 풍화토 | BJ22: =SUM(BA$6:BA21)+(BA22/2) -> 16.5 | BL22: 17 | BN22: 93
AX23: =AZ22 -> 17 | AY23: ~ | AZ23: 18 | BA23: =AZ23-AX23 -> 1 | BC23: =500*(BN23+15) -> 70000 | BD23: =IF(BA23="","",(IF(BJ23<0.5*$G$5,((BJ23/$G$5+0.125)/1.25),((BJ23/$G$5)-2)/(-3)))) -> -0.027777778 | BE23: =IF(BD23<0,0,+BD23*BA23/BC23) -> 0 | BG23: 풍화토 | BJ23: =SUM(BA$6:BA22)+(BA23/2) -> 17.5 | BL23: 18 | BN23: 125
AX24: =AZ23 -> 18 | AY24: ~ | AZ24: 19 | BA24: =AZ24-AX24 -> 1 | BC24: =500*(BN24+15) -> 70000 | BD24: =IF(BA24="","",(IF(BJ24<0.5*$G$5,((BJ24/$G$5+0.125)/1.25),((BJ24/$G$5)-2)/(-3)))) -> -0.067460317 | BE24: =IF(BD24<0,0,+BD24*BA24/BC24) -> 0 | BG24: 풍화토 | BJ24: =SUM(BA$6:BA23)+(BA24/2) -> 18.5 | BL24: 19 | BN24: 125
AX25: =AZ24 -> 19 | AY25: ~ | BA25: =AZ25-AX25 -> -19 | BC25: =500*(BN25+15) -> 114500 | BD25: =IF(BA25="","",(IF(BJ25<0.5*$G$5,((BJ25/$G$5+0.125)/1.25),((BJ25/$G$5)-2)/(-3)))) -> 0.28968254 | BE25: =IF(BD25<0,0,+BD25*BA25/BC25) -> -4.8069592e-05 | BG25: 풍화토 | BJ25: =SUM($BA$6:BA24)+(BA25/2) -> 9.5 | BL25: 20 | BN25: 214
AX26: =AZ25 -> 0 | AY26: ~ | BA26: =AZ26-AX26 -> 0 | BC26: =1200*(BN26+6) -> 264000 | BD26: =IF(BA26="","",(IF(BJ26<0.5*$G$5,((BJ26/$G$5+0.125)/1.25),((BJ26/$G$5)-2)/(-3)))) -> 0.1 | BE26: =IF(BD26<0,0,+BD26*BA26/BC26) -> 0 | BG26: 풍화암 | BJ26: =SUM($BA$6:BA25)+(BA26/2) -> 0 | BL26: 21 | BN26: 214
AX27: =AZ26 -> 0 | AY27: ~ | BA27: =AZ27-AX27 -> 0 | BC27: =1200*(BN27+6) -> 264000 | BD27: =IF(BA27="","",(IF(BJ27<0.5*$G$5,((BJ27/$G$5+0.125)/1.25),((BJ27/$G$5)-2)/(-3)))) -> 0.1 | BE27: =IF(BD27<0,0,+BD27*BA27/BC27) -> 0 | BG27: 풍화암 | BJ27: =SUM($BA$6:BA26)+(BA27/2) -> 0 | BL27: 22 | BN27: 214
AX28: =AZ27 -> 0 | AY28: ~ | BA28: =AZ28-AX28 -> 0 | BC28: =1200*(BN28+6) -> 7200 | BD28: =IF(BA28="","",(IF(BJ28<0.5*$G$5,((BJ28/$G$5+0.125)/1.25),((BJ28/$G$5)-2)/(-3)))) -> 0.1 | BE28: =IF(BD28<0,0,+BD28*BA28/BC28) -> 0 | BJ28: =SUM($BA$6:BA27)+(BA28/2) -> 0 | BL28: 23
AX29: =AZ28 -> 0 | AY29: ~ | BA29: =AZ29-AX29 -> 0 | BC29: =1200*(BN29+6) -> 7200 | BD29: =IF(BA29="","",(IF(BJ29<0.5*$G$5,((BJ29/$G$5+0.125)/1.25),((BJ29/$G$5)-2)/(-3)))) -> 0.1 | BE29: =IF(BD29<0,0,+BD29*BA29/BC29) -> 0 | BJ29: =SUM($BA$6:BA28)+(BA29/2) -> 0 | BL29: 24
AX30: =AZ29 -> 0 | AY30: ~ | BA30: =AZ30-AX30 -> 0 | BC30: =1200*(BN30+6) -> 7200 | BD30: =IF(BA30="","",(IF(BJ30<0.5*$G$5,((BJ30/$G$5+0.125)/1.25),((BJ30/$G$5)-2)/(-3)))) -> 0.1 | BE30: =IF(BD30<0,0,+BD30*BA30/BC30) -> 0 | BJ30: =SUM($BA$6:BA29)+(BA30/2) -> 0 | BL30: 25
AX31: =AZ30 -> 0 | AY31: ~ | BA31: =AZ31-AX31 -> 0 | BC31: =1200*(BN31+6) -> 7200 | BD31: =IF(BA31="","",(IF(BJ31<0.5*$G$5,((BJ31/$G$5+0.125)/1.25),((BJ31/$G$5)-2)/(-3)))) -> 0.1 | BE31: =IF(BD31<0,0,+BD31*BA31/BC31) -> 0 | BJ31: =SUM($BA$6:BA30)+(BA31/2) -> 0 | BL31: 26
AX32: =+AZ31 -> 0 | AY32: ~ | BA32: =AZ32-AX32 -> 0 | BC32: =1200*(BN32+6) -> 7200 | BD32: =IF(BA32="","",(IF(BJ32<0.5*$G$5,((BJ32/$G$5+0.125)/1.25),((BJ32/$G$5)-2)/(-3)))) -> 0.1 | BE32: =IF(BD32<0,0,+BD32*BA32/BC32) -> 0 | BJ32: =SUM($BA$6:BA31)+(BA32/2) -> 0 | BL32: 27
BE33: ∑
B37: 지반조사결과 매립층-퇴적층-풍화토-풍화암층의 순서로 지반이 구성
B38: 기초근입깊이가 7.4m로 퇴적층 위에 기초가 자리잡으며 20.0m 깊이에 기반암인 풍화암이 위치함
B39: 지지력 및 침하량 계산시 한계깊이(Hf)를 산출하거나 풍화암 2.0m까지인 22m까지 계산함
B43: 3. 강도전수 산정
B45: 1) | C45: 지반의 점착력
B46: * | C46: 기초 하부의 N 값 | H46: : | I46: 12 | K46: ( N < 30 )
C47: C=qu/2 | F47: Ø=0
...

Sheet 공법개요
B5: 현장 지반 조건에 의해 설계된 쇄석골재의 입도를 특수 배합 설계하여 지지력 및 침하량에 대응하여,
B6: 구조설계부터 배합 시골까지 하
